Workbook

Sheet Fábricas
B2: Fábrica | C2: Ordem de vendas | D2: Razão Social | E2: Cnpj | F2: Inscrição Estadual St | G2: Endereço | H2: N | I2: Bairro | J2: CEP | K2: Cidade | L2: Estado
B3: Itu | C3: 5000 | D3: HNK BR INDUSTRIA DE BEBIDAS LTDA. | E3: 50.221.019/0001-36 | F3: 387000650117 | G3: Av Primo Schincariol | H3: 2222 | I3: Chácara Flórida | J3: 13312250 | K3: Itu | L3: SP
B4: Jacarei | C4: 5238 | D4: HNK BR INDUSTRIA DE BEBIDAS LTDA. | E4: 50.221.019/0104-41 | F4: 392558326113 | G4: Av Presidente Humberto de Alencar Castelo Branco | H4: 2911 | I4: Conjunto Habitacional Marinho | J4: 12321150 | K4: Jacareí | L4: SP
B5: Araraquara | C5: 5239 | D5: HNK BR INDUSTRIA DE BEBIDAS LTDA. | E5: 50.221.019/0105-22 | F5: 181661963118 | G5: Av Marginal 01 | H5: 701 | I5: Chácara Catani | J5: 14808080 | K5: Araraquara | L5: SP
B6: Ponta Grossa | C6: 5231 | D6: HNK BR INDUSTRIA DE BEBIDAS LTDA. | E6: 50.221.019/0097-88 | F6: 911.300.50.81 | G6: Av Tocantins | H6: 199 | I6: Cara-Cara | J6: 84043610 | K6: Ponta Grossa | L6: PR

Sheet Proposta Assaí Outubro'25
AH2: =SUBTOTAL(9,AH5:AH57) -> 1067795.8 | AK2: =SUBTOTAL(9,AK5:AK57) -> 174579.83 | AN2: =SUBTOTAL(9,AN5:AN57) -> 1512745.7
B3: =SUBTOTAL(9,B5:B57) -> #N/A | V3: SUGESTÃO DE PREÇO OUT'25 | Y3: =SUBTOTAL(9,Y5:Y57) -> 2606749.2 | AA3: =SUBTOTAL(9,AA5:AA57) -> 30361.505 | AC3: Total de Investimento Gerado | AD3: TT Investimento Liberado | AE3: Diferença | AH3: Verba Calendario TPR | AK3: Back Margem | AN3: Verba Adicional | AP3: =SUBTOTAL(9,AP5:AP57) -> 2755121.3 | AV3: Margem entregue no promo
A4: Coeficiente | B4: HL Act Restrito | C4: Em caixas | D4: Categoria | E4: Marcas | F4: CÓDIGO SAP HNK | G4: CÓDIGO | H4: PRODUTO | I4: CX | J4: PALETE | K4: CARGA | L4: QTDE COMPRA | M4: QTDE PALETE | N4: QTDE CARRO | O4: CUSTO CX NF | P4: Custo Unitário | Q4: VERBA SELL IN CX | R4: * VERBA SELL IN UND | S4: VERBA ADIC CX | T4: * VERBA ADIC UND | U4: Total Investimento Liberado | V4: PREÇO REGULAR | W4: PREÇO PROMO | X4: PREÇO LIBERADO TELE | Y4: VERBA TOTAL SELL IN | Z4: TOTAL PEDIDO NF | AA4: HL | AG4: R$/HL | AH4: Verba Gerado | AI4: Verba unidade | AJ4: R$/HL | AK4: Verba Gerado | AL4: Verba unidade | AM4: R$/HL | AN4: Verba Gerado | AO4: Verba unidade | AP4: Gerado total | AQ4: Unidade total | AR4: VERBA TOTAL SELL IN | AS4: Saving | AT4: CUSTO UNI. NF | AU4: NOVO CUSTO | AX4: 50% Volume preço Promo | AY4: 50% Volume preço Televendas | AZ4: Preço Médio | BA4: Margem entregue | BC4: Cidade | BD4: Razão social | BE4: CNPJ | BF4: Inscrição estadual | BG4: Endereço | BH4: Número | BI4: Bairro | BJ4: Cidade | BK4: Estado | BL4: Cep
A5: 0.03228 | B5: =VLOOKUP(F5,Planilha3!D:F,3,0) -> 1663.6933 | C5: =B5/A5 -> 51539.444 | D5: Mainstream | E5: Amstel | F5: 904113 | G5: 1052772 | H5: CERVEJA AMSTEL 269ML | I5: 12 | J5: 336 | K5: =J5*24 -> 8064 | L5: 161280 | M5: =L5/J5 -> 480 | N5: =L5/K5 -> 20 | O5: 33.16 | P5: =O5/I5 -> 2.7633333 | Q5: =R5*I5 -> 0.6 | R5: 0.05 | S5: =T5*I5 -> 3.6 | T5: 0.3 | U5: =SUM(R5,T5) -> 0.35 | V5: =VLOOKUP(F5,'[1]Proposta HNK para Tenda'!$F:$T,15,0) -> 3.29 | W5: =VLOOKUP(F5,'[1]Proposta HNK para Tenda'!$F:$U,16,0) -> 3.09 | X5: 2.79 | Y5: =L5*(Q5+S5) -> 677376 | Z5: =L5*O5 -> 5348044.8 | AA5: =L5*12*0.269/100 -> 5206.1184 | AC5: =SUM(AI5,AL5,AO5) -> 0.3681265 | AD5: =SUM(R5,T5) -> 0.35 | AE5: =AC5-AD5 -> 0.0181265 | AG5: 19.98 | AH5: =AG5*AA5 -> 104018.25 | AI5: =AH5/L5/I5 -> 0.0537462 | AJ5: 23.87 | AK5: =AJ5*AA5 -> 124270.05 | AL5: =AK5/L5/I5 -> 0.0642103 | AM5: 93 | AN5: =AM5*AA5 -> 484169.01 | AO5: =AN5/L5/I5 -> 0.25017 | AP5: =SUM(AH5,AK5,AN5) -> 712457.3 | AQ5: =SUM(AI5,AL5,AO5) -> 0.3681265 | AR5: =Y5 -> 677376 | AS5: =AP5-AR5 -> 35081.303 | AT5: =O5/I5 -> 2.7633333 | AU5: =AT5-R5-T5 -> 2.4133333 | AV5: =(W5-AU5)/W5 -> 0.21898598 | AX5: =W5*50% -> 1.545 | AY5: =X5*50% -> 1.395 | AZ5: =AX5+AY5 -> 2.94 | BA5: =(W5-X5)/W5 -> 0.097087379 | BC5: Itu | BD5: HNK BR INDUSTRIA DE BEBIDAS LTDA. | BE5: 50.221.019/0001-36 | BF5: 387000650117 | BG5: Av Primo Schincariol | BH5: 2222 | BI5: Chácara Flórida | BJ5: 13312250 | BK5: Itu | BL5: SP
A6: 0.042 | B6: =VLOOKUP(F6,Planilha3!D:F,3,0) -> 1031.9338 | C6: =B6/A6 -> 24569.852 | D6: Mainstream | E6: Amstel | F6: 904952 | G6: 1193288 | H6: CERVEJA AMSTEL 350ML SLEEK | I6: 12 | J6: 280 | K6: =J6*24 -> 6720 | L6: =K6*8 -> 53760 | M6: =L6/J6 -> 192 | N6: =L6/K6 -> 8 | O6: 39.21 | P6: =O6/I6 -> 3.2675 | Q6: =R6*I6 -> 1.2 | R6: 0.1 | S6: =T6*I6 -> 3.24 | T6: 0.27 | U6: =SUM(R6,T6) -> 0.37 | V6: =VLOOKUP(F6,'[1]Proposta HNK para Tenda'!$F:$T,15,0) -> 3.89 | W6: =VLOOKUP(F6,'[1]Proposta HNK para Tenda'!$F:$U,16,0) -> 3.69 | X6: 3.29 | Y6: =L6*(Q6+S6) -> 238694.4 | Z6: =L6*O6 -> 2107929.6 | AA6: =L6*12*0.35/100 -> 2257.92 | AC6: =SUM(AI6,AL6,AO6) -> 0.378 | AD6: =SUM(R6,T6) -> 0.37 | AE6: =AC6-AD6 -> 0.008 | AG6: 21.4 | AH6: =AG6*AA6 -> 48319.488 | AI6: =AH6/L6/I6 -> 0.0749 | AJ6: 21.6 | AK6: =AJ6*AA6 -> 48771.072 | AL6: =AK6/L6/I6 -> 0.0756 | AM6: 65 | AN6: =AM6*AA6 -> 146764.8 | AO6: =AN6/L6/I6 -> 0.2275 | AP6: =SUM(AH6,AK6,AN6) -> 243855.36 | AQ6: =SUM(AI6,AL6,AO6) -> 0.378 | AR6: =Y6 -> 238694.4 | AS6: =AP6-AR6 -> 5160.96 | AT6: =O6/I6 -> 3.2675 | AU6: =AT6-R6-T6 -> 2.8975 | AV6: =(W6-AU6)/W6 -> 0.21476965 | AX6: =W6*50% -> 1.845 | AY6: =X6*50% -> 1.645 | AZ6: =AX6+AY6 -> 3.49 | BA6: =(W6-X6)/W6 -> 0.10840108 | BC6: Jacarei | BD6: HNK BR INDUSTRIA DE BEBIDAS LTDA. | BE6: 50.221.019/0104-41 | BF6: 392558326113 | BG6: Av Presidente Humberto de Alencar Castelo Branco | BH6: 2911 | BI6: Conjunto Habitacional Marinho | BJ6: 12321150 | BK6: Jacareí | BL6: SP
A7: 0.072 | B7: =VLOOKUP(F7,Planilha3!D:F,3,0) -> 40.23064 | C7: =B7/A7 -> 558.75888 | D7: Mainstream | E7: Amstel | F7: 905052 | G7: 1207152 | H7: CERVEJA AMSTEL LN 355ML | I7: 12 | J7: 175 | K7: =J7*24 -> 4200 | L7: 1400 | M7: =L7/J7 -> 8 | N7: =L7/K7 -> 0.33333333 | O7: 47.28 | P7: =O7/I7 -> 3.94 | Q7: =R7*I7 -> 0.6 | R7: 0.05 | S7: =T7*I7 -> 2.4 | T7: 0.2 | U7: =SUM(R7,T7) -> 0.25 | V7: =VLOOKUP(F7,'[1]Proposta HNK para Tenda'!$F:$T,15,0) -> 4.69 | W7: =VLOOKUP(F7,'[1]Proposta HNK para Tenda'!$F:$U,16,0) -> 4.49 | Y7: =L7*(Q7+S7) -> 4200 | Z7: =L7*O7 -> 66192 | AA7: =L7*12*0.355/100 -> 59.64 | AC7: =SUM(AI7,AL7,AO7) -> 0.1662465 | AD7: =SUM(R7,T7) -> 0.25 | AE7: =AC7-AD7 -> -0.0837535 | AG7: 21.03 | AH7: =AG7*AA7 -> 1254.2292 | AI7: =AH7/L7/I7 -> 0.0746565 | AJ7: 25.8 | AK7: =AJ7*AA7 -> 1538.712 | AL7: =AK7/L7/I7 -> 0.09159 | AM7: 0 | AN7: =AM7*AA7 -> 0 | AO7: =AN7/L7/I7 -> 0 | AP7: =SUM(AH7,AK7,AN7) -> 2792.9412 | AQ7: =SUM(AI7,AL7,AO7) -> 0.1662465 | AR7: =Y7 -> 4200 | AS7: =AP7-AR7 -> -1407.0588 | AT7: =O7/I7 -> 3.94 | AU7: =AT7-R7-T7 -> 3.69 | AV7: =(W7-AU7)/W7 -> 0.17817372 | AX7: =W7*100% -> 4.49 | AY7: =X7*50% -> 0 | AZ7: =AX7+AY7 -> 4.49 | BC7: Itu | BD7: HNK BR INDUSTRIA DE BEBIDAS LTDA. | BE7: 50.221.019/0001-36 | BF7: 387000650117 | BG7: Av Primo Schincariol | BH7: 2222 | BI7: Chácara Flórida | BJ7: 13312250 | BK7: Itu | BL7: SP
A8: =0.275*12/100 -> 0.033 | B8: =VLOOKUP(F8,Planilha3!D:F,3,0) -> #N/A | C8: =B8/A8 -> #N/A | D8: Mainstream | E8: Amstel | F8: 904632 | G8: 1155684 | H8: CERVEJA AMSTEL ULTRA 269 ML | I8: 12 | J8: 364 | K8: =J8*24 -> 8736 | L8: =J8*2 -> 728 | M8: =L8/J8 -> 2 | N8: =L8/K8 -> 0.083333333 | O8: 39.26 | P8: =O8/I8 -> 3.2716667 | Q8: =R8*I8 -> 1.2 | R8: 0.1 | S8: =T8*I8 -> 1.56 | T8: 0.13 | U8: =SUM(R8,T8) -> 0.23 | V8: 3.99 | W8: 3.49 | Y8: =L8*(Q8+S8) -> 2009.28 | Z8: =L8*O8 -> 28581.28 | AA8: =L8*12*0.275/100 -> 24.024 | AC8: =SUM(AI8,AL8,AO8) -> 0.2377375 | AD8: =SUM(R8,T8) -> 0.23 | AE8: =AC8-AD8 -> 0.0077375 | AG8: 86.45 | AH8: =AG8*AA8 -> 2076.8748 | AI8: =AH8/L8/I8 -> 0.2377375 | AJ8: 0 | AK8: =AJ8*AA8 -> 0 | AL8: =AK8/L8/I8 -> 0 | AM8: 0 | AN8: =AM8*AA8 -> 0 | AO8: =AN8/L8/I8 -> 0 | AP8: =SUM(AH8,AK8,AN8) -> 2076.8748 | AQ8: =SUM(AI8,AL8,AO8) -> 0.2377375 | AR8: =Y8 -> 2009.28 | AS8: =AP8-AR8 -> 67.5948 | AT8: =O8/I8 -> 3.2716667 | AU8: =AT8-R8-T8 -> 3.0416667 | AV8: =(W8-AU8)/W8 -> 0.12846227 | AX8: =W8*100% -> 3.49 | AY8: =X8*50% -> 0 | AZ8: =AX8+AY8 -> 3.49 | BC8: Itu | BD8: HNK BR INDUSTRIA DE BEBIDAS LTDA. | BE8: 50.221.019/0001-36 | BF8: 387000650117 | BG8: Av Primo Schincariol | BH8: 2222 | BI8: Chácara Flórida | BJ8: 13312250 | BK8: Itu | BL8: SP
A9: =0.275*12/100 -> 0.033 | B9: =VLOOKUP(F9,Planilha3!D:F,3,0) -> 7.6058015 | C9: =B9/A9 -> 230.47883 | D9: Mainstream | E9: Amstel | F9: 904631 | G9: 1160860 | H9: CERVEJA AMSTEL ULTRA LN 275 ML | I9: 12 | J9: 196 | K9: =J9*24 -> 4704 | L9: =J9*5 -> 980 | M9: =L9/J9 -> 5 | N9: =L9/K9 -> 0.20833333 | O9: 47.13 | P9: =O9/I9 -> 3.9275 | Q9: =R9*I9 -> 0 | R9: 0 | S9: =T9*I9 -> 0 | T9: 0 | U9: =SUM(R9,T9) -> 0 | V9: =VLOOKUP(F9,'[1]Proposta HNK para Tenda'!$F:$T,15,0) -> 4.79 | W9: =VLOOKUP(F9,'[1]Proposta HNK para Tenda'!$F:$U,16,0) -> 4.79 | Y9: =L9*(Q9+S9) -> 0 | Z9: =L9*O9 -> 46187.4 | AA9: =L9*12*0.275/100 -> 32.34 | AC9: =SUM(AI9,AL9,AO9) -> 0 | AD9: =SUM(R9,T9) -> 0 | AE9: =AC9-AD9 -> 0 | AG9: 0 | AH9: =AG9*AA9 -> 0 | AI9: =AH9/L9/I9 -> 0 | AK9: =AJ9*AA9 -> 0 | AL9: =AK9/L9/I9 -> 0 | AM9: 0 | AN9: =AM9*AA9 -> 0 | AO9: =AN9/L9/I9 -> 0 | AP9: =SUM(AH9,AK9,AN9) -> 0 | AQ9: =SUM(AI9,AL9,AO9) -> 0 | AR9: =Y9 -> 0 | AS9: =AP9-AR9 -> 0 | AT9: =O9/I9 -> 3.9275 | AU9: =AT9-R9-T9 -> 3.9275 | AV9: =(W9-AU9)/W9 -> 0.18006263 | AX9: =W9*100% -> 4.79 | AY9: =X9*50% -> 0 | AZ9: =AX9+AY9 -> 4.79 | BC9: Itu | BD9: HNK BR INDUSTRIA DE BEBIDAS LTDA. | BE9: 50.221.019/0001-36 | BF9: 387000650117 | BG9: Av Primo Schincariol | BH9: 2222 | BI9: Chácara Flórida | BJ9: 13312250 | BK9: Itu | BL9: SP
A10: 0.03228 | B10: =VLOOKUP(F10,Planilha3!D:F,3,0) -> 113.71405 | C10: =B10/A10 -> 3522.7399 | D10: Premium | E10: Eisenbahn | F10: 904194 | G10: 1153719 | H10: CERVEJA EISENBAHN PILSEN 269ML | I10: 12 | J10: 364 | K10: =J10*24 -> 8736 | L10: 17472 | M10: =L10/J10 -> 48 | N10: =L10/K10 -> 2 | O10: 31.52 | P10: =O10/I10 -> 2.6266667 | Q10: =R10*I10 -> 0 | R10: 0 | S10: =T10*I10 -> 0 | T10: 0 | U10: =SUM(R10,T10) -> 0 | V10: 3.09 | W10: 3.09 | Y10: =L10*(Q10+S10) -> 0 | Z10: =L10*O10 -> 550717.44 | AA10: =L10*12*0.269/100 -> 563.99616 | AC10: =SUM(AI10,AL10,AO10) -> 0 | AD10: =SUM(R10,T10) -> 0 | AE10: =AC10-AD10 -> 0 | AG10: 0 | AH10: =AG10*AA10 -> 0 | AI10: =AH10/L10/I10 -> 0 | AK10: =AJ10*AA10 -> 0 | AL10: =AK10/L10/I10 -> 0 | AM10: 0 | AN10: =AM10*AA10 -> 0 | AO10: =AN10/L10/I10 -> 0 | AP10: =SUM(AH10,AK10,AN10) -> 0 | AQ10: =SUM(AI10,AL10,AO10) -> 0 | AR10: =Y10 -> 0 | AS10: =AP10-AR10 -> 0 | AT10: =O10/I10 -> 2.6266667 | AU10: =AT10-R10-T10 -> 2.6266667 | AV10: =(W10-AU10)/W10 -> 0.14994606 | AX10: =W10*100% -> 3.09 | AY10: =X10*50% -> 0 | AZ10: =AX10+AY10 -> 3.09 | BC10: Itu | BD10: HNK BR INDUSTRIA DE BEBIDAS LTDA. | BE10: 50.221.019/0001-36 | BF10: 387000650117 | BG10: Av Primo Schincariol | BH10: 2222 | BI10: Chácara Flórida | BJ10: 13312250 | BK10: Itu | BL10: SP
A11: 0.042 | B11: =VLOOKUP(F11,Planilha3!D:F,3,0) -> 719.15382 | C11: =B11/A11 -> 17122.71 | D11: Premium | E11: Eisenbahn | F11: 903750 | G11: 1055249 | H11: CERVEJA EISENBAHN PILSEN 350ML | I11: 12 | J11: 280 | K11: =J11*24 -> 6720 | L11: 20160 | M11: =L11/J11 -> 72 | N11: =L11/K11 -> 3 | O11: 40.7 | P11: =O11/I11 -> 3.3916667 | Q11: =R11*I11 -> 0 | R11: 0 | S11: =T11*I11 -> 0 | T11: 0 | U11: =SUM(R11,T11) -> 0 | V11: 3.99 | W11: 3.99 | Y11: =L11*(Q11+S11) -> 0 | Z11: =L11*O11 -> 820512 | AA11: =L11*12*0.35/100 -> 846.72 | AC11: =SUM(AI11,AL11,AO11) -> 0 | AD11: =SUM(R11,T11) -> 0 | AE11: =AC11-AD11 -> 0 | AG11: 0 | AH11: =AG11*AA11 -> 0 | AI11: =AH11/L11/I11 -> 0 | AK11: =AJ11*AA11 -> 0 | AL11: =AK11/L11/I11 -> 0 | AM11: 0 | AN11: =AM11*AA11 -> 0 | AO11: =AN11/L11/I11 -> 0 | AP11: =SUM(AH11,AK11,AN11) -> 0 | AQ11: =SUM(AI11,AL11,AO11) -> 0 | AR11: =Y11 -> 0 | AS11: =AP11-AR11 -> 0 | AT11: =O11/I11 -> 3.3916667 | AU11: =AT11-R11-T11 -> 3.3916667 | AV11: =(W11-AU11)/W11 -> 0.14995823 | AX11: =W11*100% -> 3.99 | AY11: =X11*50% -> 0 | AZ11: =AX11+AY11 -> 3.99 | BC11: Itu | BD11: HNK BR INDUSTRIA DE BEBIDAS LTDA. | BE11: 50.221.019/0001-36 | BF11: 387000650117 | BG11: Av Primo Schincariol | BH11: 2222 | BI11: Chácara Flórida | BJ11: 13312250 | BK11: Itu | BL11: SP
A12: 0.0426 | B12: =VLOOKUP(F12,Planilha3!D:F,3,0) -> 44.325777 | C12: =B12/A12 -> 1040.5112 | D12: Premium | E12: Eisenbahn | F12: 901781 | G12: 1016972 | H12: CERVEJA EISENBAHN PILSEN LN 355ML | I12: 12 | J12: 175 | K12: =J12*24 -> 4200 | L12: =J12*10 -> 1750 | M12: =L12/J12 -> 10 | N12: =L12/K12 -> 0.41666667 | O12: 51.92 | P12: =O12/I12 -> 4.3266667 | Q12: =R12*I12 -> 3 | R12: 0.25 | S12: =T12*I12 -> 0.36 | T12: 0.03 | U12: =SUM(R12,T12) -> 0.28 | V12: 5.09 | W12: 4.19 | Y12: =L12*(Q12+S12) -> 5880 | Z12: =L12*O12 -> 90860 | AA12: =L12*12*0.355/100 -> 74.55 | AC12: =SUM(AI12,AL12,AO12) -> 0.28826 | AD12: =SUM(R12,T12) -> 0.28 | AE12: =AC12-AD12 -> 0.00826 | AG12: 81.2 | AH12: =AG12*AA12 -> 6053.46 | AI12: =AH12/L12/I12 -> 0.28826 | AK12: =AJ12*AA12 -> 0 | AL12: =AK12/L12/I12 -> 0 | AM12: 0 | AN12: =AM12*AA12 -> 0 | AO12: =AN12/L12/I12 -> 0 | AP12: =SUM(AH12,AK12,AN12) -> 6053.46 | AQ12: =SUM(AI12,AL12,AO12) -> 0.28826 | AR12: =Y12 -> 5880 | AS12: =AP12-AR12 -> 173.46 | AT12: =O12/I12 -> 4.3266667 | AU12: =AT12-R12-T12 -> 4.0466667 | AV12: =(W12-AU12)/W12 -> 0.034208433 | AX12: =W12*100% -> 4.19 | AY12: =X12*50% -> 0 | AZ12: =AX12+AY12 -> 4.19 | BC12: Itu | BD12: HNK BR INDUSTRIA DE BEBIDAS LTDA. | BE12: 50.221.019/0001-36 | BF12: 387000650117 | BG12: Av Primo Schincariol | BH12: 2222 | BI12: Chácara Flórida | BJ12: 13312250 | BK12: Itu | BL12: SP
A13: 0.042 | B13: =VLOOKUP(F13,Planilha3!D:F,3,0) -> 32.20274 | C13: =B13/A13 -> 766.73189 | D13: Premium | E13: Eisenbahn | F13: 904772 | G13: 1170146 | H13: CERVEJA EISENBAHN UNFILTERED LA 350ML | I13: 12 | J13: 280 | K13: =J13*24 -> 6720 | L13: =K13*1 -> 6720 | M13: =L13/J13 -> 24 | N13: =L13/K13 -> 1 | O13: 40.7 | P13: =O13/I13 -> 3.3916667 | Q13: =R13*I13 -> 0 | R13: 0 | S13: =T13*I13 -> 0 | T13: 0 | U13: =SUM(R13,T13) -> 0 | V13: 3.99 | W13: 3.99 | Y13: =L13*(Q13+S13) -> 0 | Z13: =L13*O13 -> 273504 | AA13: =L13*12*0.35/100 -> 282.24 | AC13: =SUM(AI13,AL13,AO13) -> 0 | AD13: =SUM(R13,T13) -> 0 | AE13: =AC13-AD13 -> 0 | AG13: 0 | AH13: =AG13*AA13 -> 0 | AI13: =AH13/L13/I13 -> 0 | AK13: =AJ13*AA13 -> 0 | AL13: =AK13/L13/I13 -> 0 | AM13: 0 | AN13: =AM13*AA13 -> 0 | AO13: =AN13/L13/I13 -> 0 | AP13: =SUM(AH13,AK13,AN13) -> 0 | AQ13: =SUM(AI13,AL13,AO13) -> 0 | AR13: =Y13 -> 0 | AS13: =AP13-AR13 -> 0 | AT13: =O13/I13 -> 3.3916667 | AU13: =AT13-R13-T13 -> 3.3916667 | AV13: =(W13-AU13)/W13 -> 0.14995823 | AX13: =W13*100% -> 3.99 | AY13: =X13*50% -> 0 | AZ13: =AX13+AY13 -> 3.99 | BC13: Itu | BD13: HNK BR INDUSTRIA DE BEBIDAS LTDA. | BE13: 50.221.019/0001-36 | BF13: 387000650117 | BG13: Av Primo Schincariol | BH13: 2222 | BI13: Chácara Flórida | BJ13: 13312250 | BK13: Itu | BL13: SP
A14: 0.0426 | B14: =VLOOKUP(F14,Planilha3!D:F,3,0) -> 1.8908876 | C14: =B14/A14 -> 44.387033 | D14: Premium | E14: Eisenbahn | F14: 904771 | G14: 1170180 | H14: CERVEJA EISENBAHN UNFILTERED LN 355ML | I14: 12 | J14: 175 | K14: =J14*24 -> 4200 | L14: =K14*1 -> 4200 | M14: =L14/J14 -> 24 | N14: =L14/K14 -> 1 | O14: 51.92 | P14: =O14/I14 -> 4.3266667 | Q14: =R14*I14 -> 3 | R14: 0.25 | S14: =T14*I14 -> 0.36 | T14: 0.03 | U14: =SUM(R14,T14) -> 0.28 | V14: 5.09 | W14: 4.19 | Y14: =L14*(Q14+S14) -> 14112 | Z14: =L14*O14 -> 218064 | AA14: =L14*12*0.355/100 -> 178.92 | AC14: =SUM(AI14,AL14,AO14) -> 0.28826 | AD14: =SUM(R14,T14) -> 0.28 | AE14: =AC14-AD14 -> 0.00826 | AG14: 81.2 | AH14: =AG14*AA14 -> 14528.304 | AI14: =AH14/L14/I14 -> 0.28826 | AK14: =AJ14*AA14 -> 0 | AL14: =AK14/L14/I14 -> 0 | AM14: 0 | AN14: =AM14*AA14 -> 0 | AO14: =AN14/L14/I14 -> 0 | AP14: =SUM(AH14,AK14,AN14) -> 14528.304 | AQ14: =SUM(AI14,AL14,AO14) -> 0.28826 | AR14: =Y14 -> 14112 | AS14: =AP14-AR14 -> 416.304 | AT14: =O14/I14 -> 4.3266667 | AU14: =AT14-R14-T14 -> 4.0466667 | AV14: =(W14-AU14)/W14 -> 0.034208433 | AX14: =W14*100% -> 4.19 | AY14: =X14*50% -> 0 | AZ14: =AX14+AY14 -> 4.19 | BC14: Itu | BD14: HNK BR INDUSTRIA DE BEBIDAS LTDA. | BE14: 50.221.019/0001-36 | BF14: 387000650117 | BG14: Av Primo Schincariol | BH14: 2222 | BI14: Chácara Flórida | BJ14: 13312250 | BK14: Itu | BL14: SP
A15: =0.269*8/100 -> 0.02152 | B15: =VLOOKUP(F15,Planilha3!D:F,3,0) -> 105.66937 | C15: =B15/A15 -> 4910.2865 | D15: Premium | E15: Heineken | F15: 904895 | G15: 1208101 | H15: CERVEJA HEINEKEN 0% ALCOOL LA 269ML | I15: 8 | J15: 520 | K15: =J15*26 -> 13520 | L15: 40560 | M15: =L15/J15 -> 78 | N15: =L15/K15 -> 3 | O15: 31.21 | P15: =O15/I15 -> 3.90125 | Q15: =R15*I15 -> 0.8 | R15: 0.1 | S15: =T15*I15 -> 0.64 | T15: 0.08 | U15: =SUM(R15,T15) -> 0.18 | V15: =VLOOKUP(F15,'[1]Proposta HNK para Tenda'!$F:$T,15,0) -> 4.59 | W15: =VLOOKUP(F15,'[1]Proposta HNK para Tenda'!$F:$U,16,0) -> 3.99 | Y15: =L15*(Q15+S15) -> 58406.4 | Z15: =L15*O15 -> 1265877.6 | AA15: =L15*8*0.269/100 -> 872.8512 | AC15: =SUM(AI15,AL15,AO15) -> 0.1905596 | AD15: =SUM(R15,T15) -> 0.18 | AE15: =AC15-AD15 -> 0.0105596 | AG15: 70.84 | AH15: =AG15*AA15 -> 61832.779 | AI15: =AH15/L15/I15 -> 0.1905596 | AK15: =AJ15*AA15 -> 0 | AL15: =AK15/L15/I15 -> 0 | AM15: 0 | AN15: =AM15*AA15 -> 0 | AO15: =AN15/L15/I15 -> 0 | AP15: =SUM(AH15,AK15,AN15) -> 61832.779 | AQ15: =SUM(AI15,AL15,AO15) -> 0.1905596 | AR15: =Y15 -> 58406.4 | AS15: =AP15-AR15 -> 3426.379 | AT15: =O15/I15 -> 3.90125 | AU15: =AT15-R15-T15 -> 3.72125 | AV15: =(W15-AU15)/W15 -> 0.06735589 | AX15: =W15*100% -> 3.99 | AY15: =X15*50% -> 0 | AZ15: =AX15+AY15 -> 3.99 | BC15: Ponta Grossa | BD15: HNK BR INDUSTRIA DE BEBIDAS LTDA. | BE15: 50.221.019/0097-88 | BF15: 911.300.50.81 | BG15: Av Tocantins | BH15: 199 | BI15: Cara-Cara | BJ15: 84043610 | BK15: Ponta Grossa | BL15: PR
A16: 0.042 | B16: =VLOOKUP(F16,Planilha3!D:F,3,0) -> 151.60164 | C16: =B16/A16 -> 3609.5629 | D16: Premium | E16: Heineken | F16: 904961 | G16: 1193325 | H16: CERVEJA HEINEKEN 0% ALCOOL LA 350ML SLEEK | I16: 12 | J16: 280 | K16: =J16*26 -> 7280 | L16: 21840 | M16: =L16/J16 -> 78 | N16: =L16/K16 -> 3 | O16: 58.04 | P16: =O16/I16 -> 4.8366667 | Q16: =R16*I16 -> 1.2 | R16: 0.1 | S16: =T16*I16 -> 4.2 | T16: 0.35 | U16: =SUM(R16,T16) -> 0.45 | V16: =VLOOKUP(F16,'[1]Proposta HNK para Tenda'!$F:$T,15,0) -> 5.69 | W16: =VLOOKUP(F16,'[1]Proposta HNK para Tenda'!$F:$U,16,0) -> 5.29 | Y16: =L16*(Q16+S16) -> 117936 | Z16: =L16*O16 -> 1267593.6 | AA16: =L16*12*0.35/100 -> 917.28 | AC16: =SUM(AI16,AL16,AO16) -> 0.47901 | AD16: =SUM(R16,T16) -> 0.45 | AE16: =AC16-AD16 -> 0.02901 | AG16: 33.86 | AH16: =AG16*AA16 -> 31059.101 | AI16: =AH16/L16/I16 -> 0.11851 | AK16: =AJ16*AA16 -> 0 | AL16: =AK16/L16/I16 -> 0 | AM16: 103 | AN16: =AM16*AA16 -> 94479.84 | AO16: =AN16/L16/I16 -> 0.3605 | AP16: =SUM(AH16,AK16,AN16) -> 125538.94 | AQ16: =SUM(AI16,AL16,AO16) -> 0.47901 | AR16: =Y16 -> 117936 | AS16: =AP16-AR16 -> 7602.9408 | AT16: =O16/I16 -> 4.8366667 | AU16: =AT16-R16-T16 -> 4.3866667 | AV16: =(W16-AU16)/W16 -> 0.17076244 | AX16: =W16*100% -> 5.29 | AY16: =X16*50% -> 0 | AZ16: =AX16+AY16 -> 5.29 | BC16: Ponta Grossa | BD16: HNK BR INDUSTRIA DE BEBIDAS LTDA. | BE16: 50.221.019/0097-88 | BF16: 911.300.50.81 | BG16: Av Tocantins | BH16: 199 | BI16: Cara-Cara | BJ16: 84043610 | BK16: Ponta Grossa | BL16: PR
A17: 0.0792 | B17: =VLOOKUP(F17,Planilha3!D:F,3,0) -> 143.24875 | C17: =B17/A17 -> 1808.6964 | D17: Premium | E17: Heineken | F17: 903996 | G17: 1140139 | H17: CERVEJA HEINEKEN 0% ALCOOL LN 330ML | I17: 24 | J17: 91 | K17: =J17*26 -> 2366 | L17: =J17*20 -> 1820 | M17: =L17/J17 -> 20 | N17: =L17/K17 -> 0.76923077 | O17: 142.6 | P17: =O17/I17 -> 5.9416667 | Q17: =R17*I17 -> 1.2 | R17: 0.05 | S17: =T17*I17 -> 0.24 | T17: 0.01 | U17: =SUM(R17,T17) -> 0.06 | V17: =VLOOKUP(F17,'[1]Proposta HNK para Tenda'!$F:$T,15,0) -> 6.99 | W17: =VLOOKUP(F17,'[1]Proposta HNK para Tenda'!$F:$U,16,0) -> 6.59 | Y17: =L17*(Q17+S17) -> 2620.8 | Z17: =L17*O17 -> 259532 | AA17: =L17*24*0.33/100 -> 144.144 | AC17: =SUM(AI17,AL17,AO17) -> 0.068508 | AD17: =SUM(R17,T17) -> 0.06 | AE17: =AC17-AD17 -> 0.008508 | AG17: 20.76 | AH17: =AG17*AA17 -> 2992.4294 | AI17: =AH17/L17/I17 -> 0.068508 | AK17: =AJ17*AA17 -> 0 | AL17: =AK17/L17/I17 -> 0 | AM17: 0 | AN17: =AM17*AA17 -> 0 | AO17: =AN17/L17/I17 -> 0 | AP17: =SUM(AH17,AK17,AN17) -> 2992.4294 | AQ17: =SUM(AI17,AL17,AO17) -> 0.068508 | AR17: =Y17 -> 2620.8 | AS17: =AP17-AR17 -> 371.62944 | AT17: =O17/I17 -> 5.9416667 | AU17: =AT17-R17-T17 -> 5.8816667 | AV17: =(W17-AU17)/W17 -> 0.10748609 | AX17: =W17*100% -> 6.59 | AY17: =X17*50% -> 0 | AZ17: =AX17+AY17 -> 6.59 | BC17: Ponta Grossa | BD17: HNK BR INDUSTRIA DE BEBIDAS LTDA. | BE17: 50.221.019/0097-88 | BF17: 911.300.50.81 | BG17: Av Tocantins | BH17: 199 | BI17: Cara-Cara | BJ17: 84043610 | BK17: Ponta Grossa | BL17: PR
A18: =0.269*8/100 -> 0.02152 | B18: =VLOOKUP(F18,Planilha3!D:F,3,0) -> 1756.2216 | C18: =B18/A18 -> 81608.811 | D18: Premium | E18: Heineken | F18: 904721 | G18: 1169727 | H18: CERVEJA HEINEKEN 269ML | I18: 8 | J18: 520 | K18: =J18*26 -> 13520 | L18: 270400 | M18: =L18/J18 -> 520 | N18: =L18/K18 -> 20 | O18: 31.21 | P18: =O18/I18 -> 3.90125 | Q18: =R18*I18 -> 0.8 | R18: 0.1 | S18: =T18*I18 -> 0.64 | T18: 0.08 | U18: =SUM(R18,T18) -> 0.18 | V18: =VLOOKUP(F18,'[1]Proposta HNK para Tenda'!$F:$T,15,0) -> 4.59 | W18: =VLOOKUP(F18,'[1]Proposta HNK para Tenda'!$F:$U,16,0) -> 3.99 | Y18: =L18*(Q18+S18) -> 389376 | Z18: =L18*O18 -> 8439184 | AA18: =L18*8*0.269/100 -> 5819.008 | AC18: =SUM(AI18,AL18,AO18) -> 0.1905596 | AD18: =SUM(R18,T18) -> 0.18 | AE18: =AC18-AD18 -> 0.0105596 | AG18: 70.84 | AH18: =AG18*AA18 -> 412218.53 | AI18: =AH18/L18/I18 -> 0.1905596 | AK18: =AJ18*AA18 -> 0 | AL18: =AK18/L18/I18 -> 0 | AM18: 0 | AN18: =AM18*AA18 -> 0 | AO18: =AN18/L18/I18 -> 0 | AP18: =SUM(AH18,AK18,AN18) -> 412218.53 | AQ18: =SUM(AI18,AL18,AO18) -> 0.1905596 | AR18: =Y18 -> 389376 | AS18: =AP18-AR18 -> 22842.527 | AT18: =O18/I18 -> 3.90125 | AU18: =AT18-R18-T18 -> 3.72125 | AV18: =(W18-AU18)/W18 -> 0.06735589 | AX18: =W18*100% -> 3.99 | AY18: =X18*50% -> 0 | AZ18: =AX18+AY18 -> 3.99 | BC18: Ponta Grossa | BD18: HNK BR INDUSTRIA DE BEBIDAS LTDA. | BE18: 50.221.019/0097-88 | BF18: 911.300.50.81 | BG18: Av Tocantins | BH18: 199 | BI18: Cara-Cara | BJ18: 84043610 | BK18: Ponta Grossa | BL18: PR
A19: 0.042 | B19: =VLOOKUP(F19,Planilha3!D:F,3,0) -> 2524.72 | C19: =B19/A19 -> 60112.38 | D19: Premium | E19: Heineken | F19: 904932 | G19: 1193319 | H19: CERVEJA HEINEKEN 350ML SLEEK | I19: 12 | J19: 280 | K19: =J19*26 -> 7280 | L19: =K19*25 -> 182000 | M19: =L19/J19 -> 650 | N19: =L19/K19 -> 25 | O19: 58.04 | P19: =O19/I19 -> 4.8366667 | Q19: =R19*I19 -> 1.2 | R19: 0.1 | S19: =T19*I19 -> 4.2 | T19: 0.35 | U19: =SUM(R19,T19) -> 0.45 | V19: =VLOOKUP(F19,'[1]Proposta HNK para Tenda'!$F:$T,15,0) -> 5.69 | W19: =VLOOKUP(F19,'[1]Proposta HNK para Tenda'!$F:$U,16,0) -> 5.29 | X19: 4.99 | Y19: =L19*(Q19+S19) -> 982800 | Z19: =L19*O19 -> 10563280 | AA19: =L19*12*0.35/100 -> 7644 | AC19: =SUM(AI19,AL19,AO19) -> 0.47901 | AD19: =SUM(R19,T19) -> 0.45 | AE19: =AC19-AD19 -> 0.02901 | AG19: 33.86 | AH19: =AG19*AA19 -> 258825.84 | AI19: =AH19/L19/I19 -> 0.11851 | AK19: =AJ19*AA19 -> 0 | AL19: =AK19/L19/I19 -> 0 | AM19: 103 | AN19: =AM19*AA19 -> 787332 | AO19: =AN19/L19/I19 -> 0.3605 | AP19: =SUM(AH19,AK19,AN19) -> 1046157.8 | AQ19: =SUM(AI19,AL19,AO19) -> 0.47901 | AR19: =Y19 -> 982800 | AS19: =AP19-AR19 -> 63357.84 | AT19: =O19/I19 -> 4.8366667 | AU19: =AT19-R19-T19 -> 4.3866667 | AV19: =(W19-AU19)/W19 -> 0.17076244 | AX19: =W19*50% -> 2.645 | AY19: =X19*50% -> 2.495 | AZ19: =AX19+AY19 -> 5.14 | BA19: =(W19-X19)/W19 -> 0.056710775 | BC19: Jacarei | BD19: HNK BR INDUSTRIA DE BEBIDAS LTDA. | BE19: 50.221.019/0104-41 | BF19: 392558326113 | BG19: Av Presidente Humberto de Alencar Castelo Branco | BH19: 2911 | BI19: Conjunto Habitacional Marinho | BJ19: 12321150 | BK19: Jacareí | BL19: SP
A20: =0.25*24/100 -> 0.06 | B20: =VLOOKUP(F20,Planilha3!D:F,3,0) -> 501.62261 | C20: =B20/A20 -> 8360.3768 | D20: Premium | E20: Heineken | F20: 905291 | G20: 1016561 | H20: CERVEJA HEINEKEN LN 250ML | I20: 24 | J20: 104 | K20: =J20*26 -> 2704 | L20: 10816 | M20: =L20/J20 -> 104 | N20: =L20/K20 -> 4 | O20: 107.92 | P20: =O20/I20 -> 4.4966667 | Q20: =R20*I20 -> 1.2 | R20: 0.05 | S20: =T20*I20 -> 0.72 | T20: 0.03 | U20: =SUM(R20,T20) -> 0.08 | V20: 5.29 | W20: 4.99 | Y20: =L20*(Q20+S20) -> 20766.72 | Z20: =L20*O20 -> 1167262.7 | AA20: =L20*24*0.25/100 -> 648.96 | AC20: =SUM(AI20,AL20,AO20) -> 0.0895 | AD20: =SUM(R20,T20) -> 0.08 | AE20: =AC20-AD20 -> 0.0095 | AG20: 35.8 | AH20: =AG20*AA20 -> 23232.768 | AI20: =AH20/L20/I20 -> 0.0895 | AK20: =AJ20*AA20 -> 0 | AL20: =AK20/L20/I20 -> 0 | AM20: 0 | AN20: =AM20*AA20 -> 0 | AO20: =AN20/L20/I20 -> 0 | AP20: =SUM(AH20,AK20,AN20) -> 23232.768 | AQ20: =SUM(AI20,AL20,AO20) -> 0.0895 | AR20: =Y20 -> 20766.72 | AS20: =AP20-AR20 -> 2466.048 | AT20: =O20/I20 -> 4.4966667 | AU20: =AT20-R20-T20 -> 4.4166667 | AV20: =(W20-AU20)/W20 -> 0.11489646 | AX20: =W20*100% -> 4.99 | AY20: =X20*50% -> 0 | AZ20: =AX20+AY20 -> 4.99 | BC20: Jacarei | BD20: HNK BR INDUSTRIA DE BEBIDAS LTDA. | BE20: 50.221.019/0104-41 | BF20: 392558326113 | BG20: Av Presidente Humberto de Alencar Castelo Branco | BH20: 2911 | BI20: Conjunto Habitacional Marinho | BJ20: 12321150 | BK20: Jacareí | BL20: SP
A21: 0.0792 | B21: =VLOOKUP(F21,Planilha3!D:F,3,0) -> 1279.3007 | C21: =B21/A21 -> 16152.787 | D21: Premium | E21: Heineken | F21: 903478 | G21: 1045807 | H21: CERVEJA HEINEKEN LN 330 ML | I21: 24 | J21: 91 | K21: =J21*26 -> 2366 | L21: 23660 | M21: =L21/J21 -> 260 | N21: =L21/K21 -> 10 | O21: 142.6 | P21: =O21/I21 -> 5.9416667 | Q21: =R21*I21 -> 1.2 | R21: 0.05 | S21: =T21*I21 -> 0.24 | T21: 0.01 | U21: =SUM(R21,T21) -> 0.06 | V21: =VLOOKUP(F21,'[1]Proposta HNK para Tenda'!$F:$T,15,0) -> 6.99 | W21: =VLOOKUP(F21,'[1]Proposta HNK para Tenda'!$F:$U,16,0) -> 6.59 | Y21: =L21*(Q21+S21) -> 34070.4 | Z21: =L21*O21 -> 3373916 | AA21: =L21*24*0.33/100 -> 1873.872 | AC21: =SUM(AI21,AL21,AO21) -> 0.068508 | AD21: =SUM(R21,T21) -> 0.06 | AE21: =AC21-AD21 -> 0.008508 | AG21: 20.76 | AH21: =AG21*AA21 -> 38901.583 | AI21: =AH21/L21/I21 -> 0.068508 | AK21: =AJ21*AA21 -> 0 | AL21: =AK21/L21/I21 -> 0 | AM21: 0 | AN21: =AM21*AA21 -> 0 | AO21: =AN21/L21/I21 -> 0 | AP21: =SUM(AH21,AK21,AN21) -> 38901.583 | AQ21: =SUM(AI21,AL21,AO21) -> 0.068508 | AR21: =Y21 -> 34070.4 | AS21: =AP21-AR21 -> 4831.1827 | AT21: =O21/I21 -> 5.9416667 | AU21: =AT21-R21-T21 -> 5.8816667 | AV21: =(W21-AU21)/W21 -> 0.10748609 | AX21: =W21*100% -> 6.59 | AY21: =X21*50% -> 0 | AZ21: =AX21+AY21 -> 6.59 | BC21: Araraquara | BD21: HNK BR INDUSTRIA DE BEBIDAS LTDA. | BE21: 50.221.019/0105-22 | BF21: 181661963118 | BG21: Av Marginal 01 | BH21: 701 | BI21: Chácara Catani | BJ21: 14808080 | BK21: Araraquara | BL21: SP
A22: 0.072 | B22: =VLOOKUP(F22,Planilha3!D:F,3,0) -> 156.38563 | C22: =B22/A22 -> 2172.0226 | D22: Premium | E22: Heineken | F22: 903480 | G22: 99187 | H22: CERVEJA HEINEKEN ONE WAY 600ML | I22: 12 | J22: 96 | K22: =J22*26 -> 2496 | L22: =J22*10 -> 960 | M22: =L22/J22 -> 10 | N22: =L22/K22 -> 0.38461538 | O22: 137.6 | P22: =O22/I22 -> 11.466667 | Q22: =R22*I22 -> 0 | R22: 0 | S22: =T22*I22 -> 0 | T22: 0 | U22: =SUM(R22,T22) -> 0 | V22: =VLOOKUP(F22,'[1]Proposta HNK para Tenda'!$F:$T,15,0) -> 13.49 | W22: =VLOOKUP(F22,'[1]Proposta HNK para Tenda'!$F:$U,16,0) -> 13.49 | Y22: =L22*(Q22+S22) -> 0 | Z22: =L22*O22 -> 132096 | AA22: =L22*12*0.6/100 -> 69.12 | AC22: =SUM(AI22,AL22,AO22) -> 0 | AD22: =SUM(R22,T22) -> 0 | AE22: =AC22-AD22 -> 0 | AG22: 0 | AH22: =AG22*AA22 -> 0 | AI22: =AH22/L22/I22 -> 0 | AK22: =AJ22*AA22 -> 0 | AL22: =AK22/L22/I22 -> 0 | AM22: 0 | AN22: =AM22*AA22 -> 0 | AO22: =AN22/L22/I22 -> 0 | AP22: =SUM(AH22,AK22,AN22) -> 0 | AQ22: =SUM(AI22,AL22,AO22) -> 0 | AR22: =Y22 -> 0 | AS22: =AP22-AR22 -> 0 | AT22: =O22/I22 -> 11.466667 | AU22: =AT22-R22-T22 -> 11.466667 | AV22: =(W22-AU22)/W22 -> 0.14998765 | AX22: =W22*100% -> 13.49 | AY22: =X22*50% -> 0 | AZ22: =AX22+AY22 -> 13.49 | BC22: Jacarei | BD22: HNK BR INDUSTRIA DE BEBIDAS LTDA. | BE22: 50.221.019/0104-41 | BF22: 392558326113 | BG22: Av Presidente Humberto de Alencar Castelo Branco | BH22: 2911 | BI22: Conjunto Habitacional Marinho | BJ22: 12321150 | BK22: Jacareí | BL22: SP
A23: 0.0792 | B23: 26 | C23: =B23/A23 -> 328.28283 | D23: Premium | E23: Sol | F23: 904701 | G23: 1022426 | H23: CERVEJA SOL PREMIUM LN 330ML | I23: 24 | J23: 91 | K23: 2366 | L23: 1274 | M23: =L23/J23 -> 14 | N23: =L23/K23 -> 0.53846154 | O23: 122.2 | P23: =O23/I23 -> 5.0916667 | Q23: =R23*I23 -> 1.44 | R23: 0.06 | S23: =T23*I23 -> 1.2 | T23: 0.05 | U23: =SUM(R23,T23) -> 0.11 | V23: 5.49 | W23: 5.09 | Y23: =L23*(Q23+S23) -> 3363.36 | Z23: =L23*O23 -> 155682.8 | AA23: =L23*24*0.33/100 -> 100.9008 | AC23: =SUM(AI23,AL23,AO23) -> 0.119493 | AD23: =SUM(R23,T23) -> 0.11 | AE23: =AC23-AD23 -> 0.009493 | AG23: 36.21 | AH23: =AG23*AA23 -> 3653.618 | AI23: =AH23/L23/I23 -> 0.119493 | AK23: =AJ23*AA23 -> 0 | AL23: =AK23/L23/I23 -> 0 | AM23: 0 | AN23: =AM23*AA23 -> 0 | AO23: =AN23/L23/I23 -> 0 | AP23: =SUM(AH23,AK23,AN23) -> 3653.618 | AQ23: =SUM(AI23,AL23,AO23) -> 0.119493 | AR23: =Y23 -> 3363.36 | AS23: =AP23-AR23 -> 290.25797 | AT23: =O23/I23 -> 5.0916667 | AU23: =AT23-R23-T23 -> 4.9816667 | AV23: =(W23-AU23)/W23 -> 0.021283563 | AX23: =W23*100% -> 5.09 | AY23: =X23*50% -> 0 | AZ23: =AX23+AY23 -> 5.09 | BC23: Jacarei | BD23: HNK BR INDUSTRIA DE BEBIDAS LTDA. | BE23: 50.221.019/0104-41 | BF23: 392558326113 | BG23: Av Presidente Humberto de Alencar Castelo Branco | BH23: 2911 | BI23: Conjunto Habitacional Marinho | BJ23: 12321150 | BK23: Jacareí | BL23: SP
A24: 0.0792 | B24: 26 | C24: =B24/A24 -> 328.28283 | D24: Premium | E24: Sol | F24: 905271 | G24: 1228753 | H24: CERVEJA SOL 0% PREMIUM LN 330ML | I24: 24 | J24: 91 | K24: 2366 | L24: =J24*7 -> 637 | M24: =L24/J24 -> 7 | N24: =L24/K24 -> 0.26923077 | O24: 122.2 | P24: =O24/I24 -> 5.0916667 | Q24: =R24*I24 -> 1.44 | R24: 0.06 | S24: =T24*I24 -> 1.2 | T24: 0.05 | U24: =SUM(R24,T24) -> 0.11 | V24: 5.99 | W24: 5.79 | Y24: =L24*(Q24+S24) -> 1681.68 | Z24: =L24*O24 -> 77841.4 | AA24: =L24*24*0.33/100 -> 50.4504 | AC24: =SUM(AI24,AL24,AO24) -> 0.119493 | AD24: =SUM(R24,T24) -> 0.11 | AE24: =AC24-AD24 -> 0.009493 | AG24: 36.21 | AH24: =AG24*AA24 -> 1826.809 | AI24: =AH24/L24/I24 -> 0.119493 | AK24: =AJ24*AA24 -> 0 | AL24: =AK24/L24/I24 -> 0 | AM24: 0 | AN24: =AM24*AA24 -> 0 | AO24: =AN24/L24/I24 -> 0 | AP24: =SUM(AH24,AK24,AN24) -> 1826.809 | AQ24: =SUM(AI24,AL24,AO24) -> 0.119493 | AR24: =Y24 -> 1681.68 | AS24: =AP24-AR24 -> 145.12898 | AT24: =O24/I24 -> 5.0916667 | AU24: =AT24-R24-T24 -> 4.9816667 | AV24: =(W24-AU24)/W24 -> 0.13960852 | AX24: =W24*100% -> 5.79 | AY24: =X24*50% -> 0 | AZ24: =AX24+AY24 -> 5.79 | BC24: Jacarei | BD24: HNK BR INDUSTRIA DE BEBIDAS LTDA. | BE24: 50.221.019/0104-41 | BF24: 392558326113 | BG24: Av Presidente Humberto de Alencar Castelo Branco | BH24: 2911 | BI24: Conjunto Habitacional Marinho | BJ24: 12321150 | BK24: Jacareí | BL24: SP
A25: =5*2/100 -> 0.1 | B25: =VLOOKUP(F25,Planilha3!D:F,3,0) -> 282.36335 | C25: =B25/A25 -> 2823.6335 | D25: Premium | E25: Heineken | F25: 903483 | G25: 75013 | H25: CHOPP HEINEKEN 5LT | I25: 2 | J25: 90 | K25: =J25*26 -> 2340 | L25: 2340 | M25: =L25/J25 -> 26 | N25: =L25/K25 -> 1 | O25: 177.63 | P25: =O25/I25 -> 88.815 | Q25: =R25*I25 -> 0 | R25: 0 | S25: =T25*I25 -> 0 | T25: 0 | U25: =SUM(R25,T25) -> 0 | V25: =VLOOKUP(F25,'[1]Proposta HNK para Tenda'!$F:$T,15,0) -> 113.99 | W25: =VLOOKUP(F25,'[1]Proposta HNK para Tenda'!$F:$U,16,0) -> 113.99 | Y25: =L25*(Q25+S25) -> 0 | Z25: =L25*O25 -> 415654.2 | AA25: =L25*2*5/100 -> 234 | AC25: =SUM(AI25,AL25,AO25) -> 0 | AD25: =SUM(R25,T25) -> 0 | AE25: =AC25-AD25 -> 0 | AG25: 0 | AH25: =AG25*AA25 -> 0 | AI25: =AH25/L25/I25 -> 0 | AK25: =AJ25*AA25 -> 0 | AL25: =AK25/L25/I25 -> 0 | AM25: 0 | AN25: =AM25*AA25 -> 0 | AO25: =AN25/L25/I25 -> 0 | AP25: =SUM(AH25,AK25,AN25) -> 0 | AQ25: =SUM(AI25,AL25,AO25) -> 0 | AR25: =Y25 -> 0 | AS25: =AP25-AR25 -> 0 | AT25: =O25/I25 -> 88.815 | AU25: =AT25-R25-T25 -> 88.815 | AV25: =(W25-AU25)/W25 -> 0.22085271 | AX25: =W25*100% -> 113.99 | AY25: =X25*50% -> 0 | AZ25: =AX25+AY25 -> 113.99 | BC25: Ponta Grossa | BD25: HNK BR INDUSTRIA DE BEBIDAS LTDA. | BE25: 50.221.019/0097-88 | BF25: 911.300.50.81 | BG25: Av Tocantins | BH25: 199 | BI25: Cara-Cara | BJ25: 84043610 | BK25: Ponta Grossa | BL25: PR
A26: =0.355*6/100 -> 0.0213 | C26: =B26/A26 -> 0 | D26: Premium | E26: Praya | F26: 631974 | G26: 1228751 | H26: CERVEJA PRAYA LAGER 355ML | I26: 6 | J26: 350 | K26: =J26*26 -> 9100 | L26: =J26*5 -> 1750 | M26: =L26/J26 -> 5 | N26: =L26/K26 -> 0.19230769 | O26: 33.07 | P26: =O26/I26 -> 5.5116667 | Q26: =R26*I26 -> 0 | R26: 0 | S26: =T26*I26 -> 0 | T26: 0 | U26: =SUM(R26,T26) -> 0 | V26: 6.99 | W26: 6.49 | Y26: =L26*(Q26+S26) -> 0 | Z26: =L26*O26 -> 57872.5 | AA26: =L26*I26*0.35/100 -> 36.75 | AC26: =SUM(AI26,AL26,AO26) -> 0 | AD26: =SUM(R26,T26) -> 0 | AE26: =AC26-AD26 -> 0 | AG26: 0 | AH26: =AG26*AA26 -> 0 | AI26: =AH26/L26/I26 -> 0 | AK26: =AJ26*AA26 -> 0 | AL26: =AK26/L26/I26 -> 0 | AM26: 0 | AN26: =AM26*AA26 -> 0 | AO26: =AN26/L26/I26 -> 0 | AP26: =SUM(AH26,AK26,AN26) -> 0 | AQ26: =SUM(AI26,AL26,AO26) -> 0 | AR26: =Y26 -> 0 | AS26: =AP26-AR26 -> 0 | AT26: =O26/I26 -> 5.5116667 | AU26: =AT26-R26-T26 -> 5.5116667 | AV26: =(W26-AU26)/W26 -> 0.15074474 | AX26: =W26*100% -> 6.49 | AY26: =X26*50% -> 0 | AZ26: =AX26+AY26 -> 6.49 | BC26: Itu | BD26: HNK BR INDUSTRIA DE BEBIDAS LTDA. | BE26: 50.221.019/0001-36 | BF26: 387000650117 | BG26: Av Primo Schincariol | BH26: 2222 | BI26: Chácara Flórida | BJ26: 13312250 | BK26: Itu | BL26: SP
A27: =0.355*24/100 -> 0.0852 | C27: =B27/A27 -> 0 | D27: Premium | E27: Praya | F27: 634958 | G27: 1149563 | H27: CERVEJA PRAYA RECEITA CLÁSSICA LN 355ML | I27: 24 | J27: 84 | K27: =J27*26 -> 2184 | L27: =J27*4 -> 336 | M27: =L27/J27 -> 4 | N27: =L27/K27 -> 0.15384615 | O27: 170.82 | P27: =O27/I27 -> 7.1175 | Q27: =R27*I27 -> 0 | R27: 0 | S27: =T27*I27 -> 0 | T27: 0 | U27: =SUM(R27,T27) -> 0 | V27: 9.49 | W27: 8.49 | Y27: =L27*(Q27+S27) -> 0 | Z27: =L27*O27 -> 57395.52 | AA27: =L27*I27*0.35/100 -> 28.224 | AC27: =SUM(AI27,AL27,AO27) -> 0 | AD27: =SUM(R27,T27) -> 0 | AE27: =AC27-AD27 -> 0 | AG27: 0 | AH27: =AG27*AA27 -> 0 | AI27: =AH27/L27/I27 -> 0 | AK27: =AJ27*AA27 -> 0 | AL27: =AK27/L27/I27 -> 0 | AM27: 0 | AN27: =AM27*AA27 -> 0 | AO27: =AN27/L27/I27 -> 0 | AP27: =SUM(AH27,AK27,AN27) -> 0 | AQ27: =SUM(AI27,AL27,AO27) -> 0 | AR27: =Y27 -> 0 | AS27: =AP27-AR27 -> 0 | AT27: =O27/I27 -> 7.1175 | AU27: =AT27-R27-T27 -> 7.1175 | AV27: =(W27-AU27)/W27 -> 0.16166078 | AX27: =W27*100% -> 8.49 | AY27: =X27*50% -> 0 | AZ27: =AX27+AY27 -> 8.49 | BC27: Itu | BD27: HNK BR INDUSTRIA DE BEBIDAS LTDA. | BE27: 50.221.019/0001-36 | BF27: 387000650117 | BG27: Av Primo Schincariol | BH27: 2222 | BI27: Chácara Flórida | BJ27: 13312250 | BK27: Itu | BL27: SP
A28: =0.6*12/100 -> 0.072 | C28: =B28/A28 -> 0 | D28: Premium | E28: Praya | F28: 634957 | G28: 1149565 | H28: CERVEJA PRAYA RECEITA CLÁSSICA 600ML | I28: 12 | J28: 60 | K28: =J28*26 -> 1560 | L28: =J28*14 -> 840 | M28: =L28/J28 -> 14 | N28: =L28/K28 -> 0.53846154 | O28: 136.71 | P28: =O28/I28 -> 11.3925 | Q28: =R28*I28 -> 0 | R28: 0 | S28: =T28*I28 -> 0 | T28: 0 | U28: =SUM(R28,T28) -> 0 | V28: 15.19 | W28: 13.29 | Y28: =L28*(Q28+S28) -> 0 | Z28: =L28*O28 -> 114836.4 | AA28: =L28*I28*0.6/100 -> 60.48 | AC28: =SUM(AI28,AL28,AO28) -> 0 | AD28: =SUM(R28,T28) -> 0 | AE28: =AC28-AD28 -> 0 | AG28: 0 | AH28: =AG28*AA28 -> 0 | AI28: =AH28/L28/I28 -> 0 | AK28: =AJ28*AA28 -> 0 | AL28: =AK28/L28/I28 -> 0 | AM28: 0 | AN28: =AM28*AA28 -> 0 | AO28: =AN28/L28/I28 -> 0 | AP28: =SUM(AH28,AK28,AN28) -> 0 | AQ28: =SUM(AI28,AL28,AO28) -> 0 | AR28: =Y28 -> 0 | AS28: =AP28-AR28 -> 0 | AT28: =O28/I28 -> 11.3925 | AU28: =AT28-R28-T28 -> 11.3925 | AV28: =(W28-AU28)/W28 -> 0.14277652 | AX28: =W28*100% -> 13.29 | AY28: =X28*50% -> 0 | AZ28: =AX28+AY28 -> 13.29 | BC28: Itu | BD28: HNK BR INDUSTRIA DE BEBIDAS LTDA. | BE28: 50.221.019/0001-36 | BF28: 387000650117 | BG28: Av Primo Schincariol | BH28: 2222 | BI28: Chácara Flórida | BJ28: 13312250 | BK28: Itu | BL28: SP
A29: 0.072 | B29: =VLOOKUP(F29,Planilha3!D:F,3,0) -> 7.4611665 | C29: =B29/A29 -> 103.62731 | D29: Craft | E29: Baden | F29: 902832 | G29: 1046669 | H29: CERVEJA BADEN IPA 600ML | I29: 12 | J29: 60 | K29: =J29*24 -> 1440 | L29: 600 | M29: =L29/J29 -> 10 | N29: =L29/K29 -> 0.41666667 | O29: 134.52 | P29: =O29/I29 -> 11.21 | Q29: =R29*I29 -> 0 | R29: 0 | S29: =T29*I29 -> 0 | T29: 0 | U29: =SUM(R29,T29) -> 0 | V29: =VLOOKUP(F29,'[1]Proposta HNK para Tenda'!$F:$T,15,0) -> 14.19 | W29: =VLOOKUP(F29,'[1]Proposta HNK para Tenda'!$F:$U,16,0) -> 14.19 | Y29: =L29*(Q29+S29) -> 0 | Z29: =L29*O29 -> 80712 | AA29: =L29*12*0.6/100 -> 43.2 | AC29: =SUM(AI29,AL29,AO29) -> 0 | AD29: =SUM(R29,T29) -> 0 | AE29: =AC29-AD29 -> 0 | AG29: 0 | AH29: =AG29*AA29 -> 0 | AI29: =AH29/L29/I29 -> 0 | AK29: =AJ29*AA29 -> 0 | AL29: =AK29/L29/I29 -> 0 | AM29: 0 | AN29: =AM29*AA29 -> 0 | AO29: =AN29/L29/I29 -> 0 | AP29: =SUM(AH29,AK29,AN29) -> 0 | AQ29: =SUM(AI29,AL29,AO29) -> 0 | AR29: =Y29 -> 0 | AS29: =AP29-AR29 -> 0 | AT29: =O29/I29 -> 11.21 | AU29: =AT29-R29-T29 -> 11.21 | AV29: =(W29-AU29)/W29 -> 0.21000705 | AX29: =W29*100% -> 14.19 | AY29: =X29*50% -> 0 | AZ29: =AX29+AY29 -> 14.19 | BC29: Itu | BD29: HNK BR INDUSTRIA DE BEBIDAS LTDA. | BE29: 50.221.019/0001-36 | BF29: 387000650117 | BG29: Av Primo Schincariol | BH29: 2222 | BI29: Chácara Flórida | BJ29: 13312250 | BK29: Itu | BL29: SP
A30: 0.072 | B30: =VLOOKUP(F30,Planilha3!D:F,3,0) -> 5.948199 | C30: =B30/A30 -> 82.613875 | D30: Craft | E30: Baden | F30: 900118 | G30: 1017028 | H30: CERVEJA BADEN GOLDEN 600ML | I30: 12 | J30: 60 | K30: =J30*24 -> 1440 | L30: 80 | M30: =L30/J30 -> 1.3333333 | N30: =L30/K30 -> 0.055555556 | O30: 134.52 | P30: =O30/I30 -> 11.21 | Q30: =R30*I30 -> 0 | R30: 0 | S30: =T30*I30 -> 0 | T30: 0 | U30: =SUM(R30,T30) -> 0 | V30: =VLOOKUP(F30,'[1]Proposta HNK para Tenda'!$F:$T,15,0) -> 14.19 | W30: =VLOOKUP(F30,'[1]Proposta HNK para Tenda'!$F:$U,16,0) -> 14.19 | Y30: =L30*(Q30+S30) -> 0 | Z30: =L30*O30 -> 10761.6 | AA30: =L30*12*0.6/100 -> 5.76 | AC30: =SUM(AI30,AL30,AO30) -> 0 | AD30: =SUM(R30,T30) -> 0 | AE30: =AC30-AD30 -> 0 | AG30: 0 | AH30: =AG30*AA30 -> 0 | AI30: =AH30/L30/I30 -> 0 | AK30: =AJ30*AA30 -> 0 | AL30: =AK30/L30/I30 -> 0 | AM30: 0 | AN30: =AM30*AA30 -> 0 | AO30: =AN30/L30/I30 -> 0 | AP30: =SUM(AH30,AK30,AN30) -> 0 | AQ30: =SUM(AI30,AL30,AO30) -> 0 | AR30: =Y30 -> 0 | AS30: =AP30-AR30 -> 0 | AT30: =O30/I30 -> 11.21 | AU30: =AT30-R30-T30 -> 11.21 | AV30: =(W30-AU30)/W30 -> 0.21000705 | AX30: =W30*100% -> 14.19 | AY30: =X30*50% -> 0 | AZ30: =AX30+AY30 -> 14.19 | BC30: Itu | BD30: HNK BR INDUSTRIA DE BEBIDAS LTDA. | BE30: 50.221.019/0001-36 | BF30: 387000650117 | BG30: Av Primo Schincariol | BH30: 2222 | BI30: Chácara Flórida | BJ30: 13312250 | BK30: Itu | BL30: SP
A31: 0.042 | B31: =VLOOKUP(F31,Planilha3!D:F,3,0) -> 27.698971 | C31: =B31/A31 -> 659.49932 | D31: Craft | E31: Baden | F31: 904451 | G31: 1147973 | H31: CERVEJA BADEN IPA LA 350ML | I31: 12 | J31: 280 | K31: =J31*24 -> 6720 | L31: 840 | M31: =L31/J31 -> 3 | N31: =M31/26 -> 0.11538462 | O31: 57.73 | P31: =O31/I31 -> 4.8108333 | Q31: =R31*I31 -> 3 | R31: 0.25 | S31: =T31*I31 -> 0.72 | T31: 0.06 | U31: =SUM(R31,T31) -> 0.31 | V31: =VLOOKUP(F31,'[1]Proposta HNK para Tenda'!$F:$T,15,0) -> 6.09 | W31: =VLOOKUP(F31,'[1]Proposta HNK para Tenda'!$F:$U,16,0) -> 5.39 | Y31: =L31*(Q31+S31) -> 3124.8 | Z31: =L31*O31 -> 48493.2 | AA31: =L31*12*0.35/100 -> 35.28 | AC31: =SUM(AI31,AL31,AO31) -> 0.3143 | AD31: =SUM(R31,T31) -> 0.31 | AE31: =AC31-AD31 -> 0.0043 | AG31: 89.8 | AH31: =AG31*AA31 -> 3168.144 | AI31: =AH31/L31/I31 -> 0.3143 | AK31: =AJ31*AA31 -> 0 | AL31: =AK31/L31/I31 -> 0 | AM31: 0 | AN31: =AM31*AA31 -> 0 | AO31: =AN31/L31/I31 -> 0 | AP31: =SUM(AH31,AK31,AN31) -> 3168.144 | AQ31: =SUM(AI31,AL31,AO31) -> 0.3143 | AR31: =Y31 -> 3124.8 | AS31: =AP31-AR31 -> 43.344 | AT31: =O31/I31 -> 4.8108333 | AU31: =AT31-R31-T31 -> 4.5008333 | AV31: =(W31-AU31)/W31 -> 0.16496599 | AX31: =W31*100% -> 5.39 | AY31: =X31*50% -> 0 | AZ31: =AX31+AY31 -> 5.39 | BC31: Itu | BD31: HNK BR INDUSTRIA DE BEBIDAS LTDA. | BE31: 50.221.019/0001-36 | BF31: 387000650117 | BG31: Av Primo Schincariol | BH31: 2222 | BI31: Chácara Flórida | BJ31: 13312250 | BK31: Itu | BL31: SP
A32: 0.072 | B32: =VLOOKUP(F32,Planilha3!D:F,3,0) -> 2.958687 | C32: =B32/A32 -> 41.092875 | D32: Craft | E32: Baden | F32: 904742 | G32: 1169732 | H32: CERVEJA BADEN PEACH 600ML | I32: 12 | J32: 60 | K32: =J32*24 -> 1440 | L32: =J32*5 -> 300 | M32: =L32/J32 -> 5 | N32: =L32/K32 -> 0.20833333 | O32: 134.52 | P32: =O32/I32 -> 11.21 | Q32: =R32*I32 -> 0 | R32: 0 | S32: =T32*I32 -> 0 | T32: 0 | U32: =SUM(R32,T32) -> 0 | V32: =VLOOKUP(F32,'[1]Proposta HNK para Tenda'!$F:$T,15,0) -> 14.19 | W32: =VLOOKUP(F32,'[1]Proposta HNK para Tenda'!$F:$U,16,0) -> 14.19 | Y32: =L32*(Q32+S32) -> 0 | Z32: =L32*O32 -> 40356 | AA32: =L32*12*0.6/100 -> 21.6 | AC32: =SUM(AI32,AL32,AO32) -> 0 | AD32: =SUM(R32,T32) -> 0 | AE32: =AC32-AD32 -> 0 | AG32: 0 | AH32: =AG32*AA32 -> 0 | AI32: =AH32/L32/I32 -> 0 | AK32: =AJ32*AA32 -> 0 | AL32: =AK32/L32/I32 -> 0 | AM32: 0 | AN32: =AM32*AA32 -> 0 | AO32: =AN32/L32/I32 -> 0 | AP32: =SUM(AH32,AK32,AN32) -> 0 | AQ32: =SUM(AI32,AL32,AO32) -> 0 | AR32: =Y32 -> 0 | AS32: =AP32-AR32 -> 0 | AT32: =O32/I32 -> 11.21 | AU32: =AT32-R32-T32 -> 11.21 | AV32: =(W32-AU32)/W32 -> 0.21000705 | AX32: =W32*100% -> 14.19 | AY32: =X32*50% -> 0 | AZ32: =AX32+AY32 -> 14.19 | BC32: Itu | BD32: HNK BR INDUSTRIA DE BEBIDAS LTDA. | BE32: 50.221.019/0001-36 | BF32: 387000650117 | BG32: Av Primo Schincariol | BH32: 2222 | BI32: Chácara Flórida | BJ32: 13312250 | BK32: Itu | BL32: SP
A33: 0.042 | B33: =VLOOKUP(F33,Planilha3!D:F,3,0) -> 12.871838 | C33: =B33/A33 -> 306.47234 | D33: Craft | E33: Baden | F33: 904743 | G33: 1170232 | H33: CERVEJA BADEN PEACH LA 350ML | I33: 12 | J33: 280 | K33: =J33*24 -> 6720 | L33: 560 | M33: =L33/J33 -> 2 | N33: =L33/K33 -> 0.083333333 | O33: 57.73 | P33: =O33/I33 -> 4.8108333 | Q33: =R33*I33 -> 3 | R33: 0.25 | S33: =T33*I33 -> 0.72 | T33: 0.06 | U33: =SUM(R33,T33) -> 0.31 | V33: =VLOOKUP(F33,'[1]Proposta HNK para Tenda'!$F:$T,15,0) -> 6.09 | W33: =VLOOKUP(F33,'[1]Proposta HNK para Tenda'!$F:$U,16,0) -> 5.39 | Y33: =L33*(Q33+S33) -> 2083.2 | Z33: =L33*O33 -> 32328.8 | AA33: =L33*12*0.35/100 -> 23.52 | AC33: =SUM(AI33,AL33,AO33) -> 0.3143 | AD33: =SUM(R33,T33) -> 0.31 | AE33: =AC33-AD33 -> 0.0043 | AG33: 89.8 | AH33: =AG33*AA33 -> 2112.096 | AI33: =AH33/L33/I33 -> 0.3143 | AK33: =AJ33*AA33 -> 0 | AL33: =AK33/L33/I33 -> 0 | AM33: 0 | AN33: =AM33*AA33 -> 0 | AO33: =AN33/L33/I33 -> 0 | AP33: =SUM(AH33,AK33,AN33) -> 2112.096 | AQ33: =SUM(AI33,AL33,AO33) -> 0.3143 | AR33: =Y33 -> 2083.2 | AS33: =AP33-AR33 -> 28.896 | AT33: =O33/I33 -> 4.8108333 | AU33: =AT33-R33-T33 -> 4.5008333 | AV33: =(W33-AU33)/W33 -> 0.16496599 | AX33: =W33*100% -> 5.39 | AY33: =X33*50% -> 0 | AZ33: =AX33+AY33 -> 5.39 | BC33: Itu | BD33: HNK BR INDUSTRIA DE BEBIDAS LTDA. | BE33: 50.221.019/0001-36 | BF33: 387000650117 | BG33: Av Primo Schincariol | BH33: 2222 | BI33: Chácara Flórida | BJ33: 13312250 | BK33: Itu | BL33: SP
A34: 0.072 | B34: =VLOOKUP(F34,Planilha3!D:F,3,0) -> 5.1478175 | C34: =B34/A34 -> 71.497465 | D34: Craft | E34: Baden | F34: 900109 | G34: 1017027 | H34: CERVEJA BADEN CRISTAL 600ML | I34: 12 | J34: 60 | K34: =J34*24 -> 1440 | L34: 160 | M34: =L34/J34 -> 2.6666667 | N34: =L34/K34 -> 0.11111111 | O34: 134.52 | P34: =O34/I34 -> 11.21 | Q34: =R34*I34 -> 0 | R34: 0 | S34: =T34*I34 -> 0 | T34: 0 | U34: =SUM(R34,T34) -> 0 | V34: =VLOOKUP(F34,'[1]Proposta HNK para Tenda'!$F:$T,15,0) -> 14.19 | W34: =VLOOKUP(F34,'[1]Proposta HNK para Tenda'!$F:$U,16,0) -> 14.19 | Y34: =L34*(Q34+S34) -> 0 | Z34: =L34*O34 -> 21523.2 | AA34: =L34*12*0.6/100 -> 11.52 | AC34: =SUM(AI34,AL34,AO34) -> 0 | AD34: =SUM(R34,T34) -> 0 | AE34: =AC34-AD34 -> 0 | AG34: 0 | AH34: =AG34*AA34 -> 0 | AI34: =AH34/L34/I34 -> 0 | AK34: =AJ34*AA34 -> 0 | AL34: =AK34/L34/I34 -> 0 | AM34: 0 | AN34: =AM34*AA34 -> 0 | AO34: =AN34/L34/I34 -> 0 | AP34: =SUM(AH34,AK34,AN34) -> 0 | AQ34: =SUM(AI34,AL34,AO34) -> 0 | AR34: =Y34 -> 0 | AS34: =AP34-AR34 -> 0 | AT34: =O34/I34 -> 11.21 | AU34: =AT34-R34-T34 -> 11.21 | AV34: =(W34-AU34)/W34 -> 0.21000705 | AX34: =W34*100% -> 14.19 | AY34: =X34*50% -> 0 | AZ34: =AX34+AY34 -> 14.19 | BC34: Itu | BD34: HNK BR INDUSTRIA DE BEBIDAS LTDA. | BE34: 50.221.019/0001-36 | BF34: 387000650117 | BG34: Av Primo Schincariol | BH34: 2222 | BI34: Chácara Flórida | BJ34: 13312250 | BK34: Itu | BL34: SP
A35: 0.042 | B35: =VLOOKUP(F35,Planilha3!D:F,3,0) -> 8.3101108 | C35: =B35/A35 -> 197.85978 | D35: Craft | E35: Baden | F35: 904441 | G35: 1147975 | H35: CERVEJA BADEN CRISTAL LA 350ML | I35: 12 | J35: 280 | K35: =J35*24 -> 6720 | L35: 560 | M35: =L35/J35 -> 2 | N35: =L35/K35 -> 0.083333333 | O35: 57.73 | P35: =O35/I35 -> 4.8108333 | Q35: =R35*I35 -> 3 | R35: 0.25 | S35: =T35*I35 -> 0.72 | T35: 0.06 | U35: =SUM(R35,T35) -> 0.31 | V35: =VLOOKUP(F35,'[1]Proposta HNK para Tenda'!$F:$T,15,0) -> 6.09 | W35: =VLOOKUP(F35,'[1]Proposta HNK para Tenda'!$F:$U,16,0) -> 5.39 | Y35: =L35*(Q35+S35) -> 2083.2 | Z35: =L35*O35 -> 32328.8 | AA35: =L35*12*0.35/100 -> 23.52 | AC35: =SUM(AI35,AL35,AO35) -> 0.3143 | AD35: =SUM(R35,T35) -> 0.31 | AE35: =AC35-AD35 -> 0.0043 | AG35: 89.8 | AH35: =AG35*AA35 -> 2112.096 | AI35: =AH35/L35/I35 -> 0.3143 | AK35: =AJ35*AA35 -> 0 | AL35: =AK35/L35/I35 -> 0 | AM35: 0 | AN35: =AM35*AA35 -> 0 | AO35: =AN35/L35/I35 -> 0 | AP35: =SUM(AH35,AK35,AN35) -> 2112.096 | AQ35: =SUM(AI35,AL35,AO35) -> 0.3143 | AR35: =Y35 -> 2083.2 | AS35: =AP35-AR35 -> 28.896 | AT35: =O35/I35 -> 4.8108333 | AU35: =AT35-R35-T35 -> 4.5008333 | AV35: =(W35-AU35)/W35 -> 0.16496599 | AX35: =W35*100% -> 5.39 | AY35: =X35*50% -> 0 | AZ35: =AX35+AY35 -> 5.39 | BC35: Itu | BD35: HNK BR INDUSTRIA DE BEBIDAS LTDA. | BE35: 50.221.019/0001-36 | BF35: 387000650117 | BG35: Av Primo Schincariol | BH35: 2222 | BI35: Chácara Flórida | BJ35: 13312250 | BK35: Itu | BL35: SP
A36: 0.072 | B36: =VLOOKUP(F36,Planilha3!D:F,3,0) -> 6.1719833 | C36: =B36/A36 -> 85.72199 | D36: Craft | E36: Baden | F36: 901162 | G36: 1046689 | H36: CERVEJA BADEN WITIBIER 600ML | I36: 12 | J36: 60 | K36: =J36*24 -> 1440 | L36: 160 | M36: =L36/J36 -> 2.6666667 | N36: =L36/K36 -> 0.11111111 | O36: 134.52 | P36: =O36/I36 -> 11.21 | Q36: =R36*I36 -> 0 | R36: 0 | S36: =T36*I36 -> 0 | T36: 0 | U36: =SUM(R36,T36) -> 0 | V36: =VLOOKUP(F36,'[1]Proposta HNK para Tenda'!$F:$T,15,0) -> 14.19 | W36: =VLOOKUP(F36,'[1]Proposta HNK para Tenda'!$F:$U,16,0) -> 14.19 | Y36: =L36*(Q36+S36) -> 0 | Z36: =L36*O36 -> 21523.2 | AA36: =L36*12*0.6/100 -> 11.52 | AC36: =SUM(AI36,AL36,AO36) -> 0 | AD36: =SUM(R36,T36) -> 0 | AE36: =AC36-AD36 -> 0 | AG36: 0 | AH36: =AG36*AA36 -> 0 | AI36: =AH36/L36/I36 -> 0 | AK36: =AJ36*AA36 -> 0 | AL36: =AK36/L36/I36 -> 0 | AM36: 0 | AN36: =AM36*AA36 -> 0 | AO36: =AN36/L36/I36 -> 0 | AP36: =SUM(AH36,AK36,AN36) -> 0 | AQ36: =SUM(AI36,AL36,AO36) -> 0 | AR36: =Y36 -> 0 | AS36: =AP36-AR36 -> 0 | AT36: =O36/I36 -> 11.21 | AU36: =AT36-R36-T36 -> 11.21 | AV36: =(W36-AU36)/W36 -> 0.21000705 | AX36: =W36*100% -> 14.19 | AY36: =X36*50% -> 0 | AZ36: =AX36+AY36 -> 14.19 | BC36: Itu | BD36: HNK BR INDUSTRIA DE BEBIDAS LTDA. | BE36: 50.221.019/0001-36 | BF36: 387000650117 | BG36: Av Primo Schincariol | BH36: 2222 | BI36: Chácara Flórida | BJ36: 13312250 | BK36: Itu | BL36: SP
A37: 0.042 | B37: =VLOOKUP(F37,Planilha3!D:F,3,0) -> 21.928826 | C37: =B37/A37 -> 522.11489 | D37: Craft | E37: Baden | F37: 904193 | G37: 1150647 | H37: CERVEJA BADEN WITBIER LA 350ML | I37: 12 | J37: 280 | K37: =J37*24 -> 6720 | L37: 560 | M37: =L37/J37 -> 2 | N37: =L37/K37 -> 0.083333333 | O37: 57.73 | P37: =O37/I37 -> 4.8108333 | Q37: =R37*I37 -> 3 | R37: 0.25 | S37: =T37*I37 -> 0.72 | T37: 0.06 | U37: =SUM(R37,T37) -> 0.31 | V37: =VLOOKUP(F37,'[1]Proposta HNK para Tenda'!$F:$T,15,0) -> 6.09 | W37: =VLOOKUP(F37,'[1]Proposta HNK para Tenda'!$F:$U,16,0) -> 5.39 | Y37: =L37*(Q37+S37) -> 2083.2 | Z37: =L37*O37 -> 32328.8 | AA37: =L37*12*0.35/100 -> 23.52 | AC37: =SUM(AI37,AL37,AO37) -> 0.3143 | AD37: =SUM(R37,T37) -> 0.31 | AE37: =AC37-AD37 -> 0.0043 | AG37: 89.8 | AH37: =AG37*AA37 -> 2112.096 | AI37: =AH37/L37/I37 -> 0.3143 | AK37: =AJ37*AA37 -> 0 | AL37: =AK37/L37/I37 -> 0 | AM37: 0 | AN37: =AM37*AA37 -> 0 | AO37: =AN37/L37/I37 -> 0 | AP37: =SUM(AH37,AK37,AN37) -> 2112.096 | AQ37: =SUM(AI37,AL37,AO37) -> 0.3143 | AR37: =Y37 -> 2083.2 | AS37: =AP37-AR37 -> 28.896 | AT37: =O37/I37 -> 4.8108333 | AU37: =AT37-R37-T37 -> 4.5008333 | AV37: =(W37-AU37)/W37 -> 0.16496599 | AX37: =W37*100% -> 5.39 | AY37: =X37*50% -> 0 | AZ37: =AX37+AY37 -> 5.39 | BC37: Itu | BD37: HNK BR INDUSTRIA DE BEBIDAS LTDA. | BE37: 50.221.019/0001-36 | BF37: 387000650117 | BG37: Av Primo Schincariol | BH37: 2222 | BI37: Chácara Flórida | BJ37: 13312250 | BK37: Itu | BL37: SP
A38: 0.042 | B38: =VLOOKUP(F38,Planilha3!D:F,3,0) -> 12.387493 | C38: =B38/A38 -> 294.94032 | D38: Craft | E38: Blue Moon | F38: 904612 | G38: 1155188 | H38: CERVEJA BLUE MOON LA 350ML | I38: 12 | J38: 280 | K38: =J38*24 -> 6720 | L38: 280 | M38: =L38/J38 -> 1 | N38: =L38/K38 -> 0.041666667 | O38: 85.23 | P38: =O38/I38 -> 7.1025 | Q38: =R38*I38 -> 10.8 | R38: 0.9 | S38: =T38*I38 -> 0.24 | T38: 0.02 | U38: =SUM(R38,T38) -> 0.92 | V38: =VLOOKUP(F38,'[1]Proposta HNK para Tenda'!$F:$T,15,0) -> 8.99 | W38: =VLOOKUP(F38,'[1]Proposta HNK para Tenda'!$F:$U,16,0) -> 6.99 | Y38: =L38*(Q38+S38) -> 3091.2 | Z38: =L38*O38 -> 23864.4 | AA38: =L38*12*0.35/100 -> 11.76 | AC38: =SUM(AI38,AL38,AO38) -> 0.93051 | AD38: =SUM(R38,T38) -> 0.92 | AE38: =AC38-AD38 -> 0.01051 | AG38: 265.86 | AH38: =AG38*AA38 -> 3126.5136 | AI38: =AH38/L38/I38 -> 0.93051 | AK38: =AJ38*AA38 -> 0 | AL38: =AK38/L38/I38 -> 0 | AM38: 0 | AN38: =AM38*AA38 -> 0 | AO38: =AN38/L38/I38 -> 0 | AP38: =SUM(AH38,AK38,AN38) -> 3126.5136 | AQ38: =SUM(AI38,AL38,AO38) -> 0.93051 | AR38: =Y38 -> 3091.2 | AS38: =AP38-AR38 -> 35.3136 | AT38: =O38/I38 -> 7.1025 | AU38: =AT38-R38-T38 -> 6.1825 | AV38: =(W38-AU38)/W38 -> 0.11552217 | AX38: =W38*100% -> 6.99 | AY38: =X38*50% -> 0 | AZ38: =AX38+AY38 -> 6.99 | BC38: Itu | BD38: HNK BR INDUSTRIA DE BEBIDAS LTDA. | BE38: 50.221.019/0001-36 | BF38: 387000650117 | BG38: Av Primo Schincariol | BH38: 2222 | BI38: Chácara Flórida | BJ38: 13312250 | BK38: Itu | BL38: SP
A39: 0.0852 | B39: =VLOOKUP(F39,Planilha3!D:F,3,0) -> 5.009831 | C39: =B39/A39 -> 58.800833 | D39: Craft | E39: Blue Moon | F39: 904602 | G39: 1160869 | H39: CERVEJA BLUE MOON LN 355ML | I39: 24 | J39: 56 | K39: =J39*24 -> 1344 | L39: =J39*2 -> 112 | M39: =L39/J39 -> 2 | N39: =L39/K39 -> 0.083333333 | O39: 208.37 | P39: =O39/I39 -> 8.6820833 | Q39: =R39*I39 -> 0 | R39: 0 | S39: =T39*I39 -> 0 | T39: 0 | U39: =SUM(R39,T39) -> 0 | V39: =VLOOKUP(F39,'[1]Proposta HNK para Tenda'!$F:$T,15,0) -> 10.99 | W39: =VLOOKUP(F39,'[1]Proposta HNK para Tenda'!$F:$U,16,0) -> 10.99 | Y39: =L39*(Q39+S39) -> 0 | Z39: =L39*O39 -> 23337.44 | AA39: =L39*24*0.355/100 -> 9.5424 | AC39: =SUM(AI39,AL39,AO39) -> 0 | AD39: =SUM(R39,T39) -> 0 | AE39: =AC39-AD39 -> 0 | AG39: 0 | AH39: =AG39*AA39 -> 0 | AI39: =AH39/L39/I39 -> 0 | AK39: =AJ39*AA39 -> 0 | AL39: =AK39/L39/I39 -> 0 | AM39: 0 | AN39: =AM39*AA39 -> 0 | AO39: =AN39/L39/I39 -> 0 | AP39: =SUM(AH39,AK39,AN39) -> 0 | AQ39: =SUM(AI39,AL39,AO39) -> 0 | AR39: =Y39 -> 0 | AS39: =AP39-AR39 -> 0 | AT39: =O39/I39 -> 8.6820833 | AU39: =AT39-R39-T39 -> 8.6820833 | AV39: =(W39-AU39)/W39 -> 0.21000152 | AX39: =W39*100% -> 10.99 | AY39: =X39*50% -> 0 | AZ39: =AX39+AY39 -> 10.99 | BC39: Itu | BD39: HNK BR INDUSTRIA DE BEBIDAS LTDA. | BE39: 50.221.019/0001-36 | BF39: 387000650117 | BG39: Av Primo Schincariol | BH39: 2222 | BI39: Chácara Flórida | BJ39: 13312250 | BK39: Itu | BL39: SP
A40: 0.042 | B40: =VLOOKUP(F40,Planilha3!D:F,3,0) -> 17.452561 | C40: =B40/A40 -> 415.53717 | D40: Craft | E40: Eisenbahn | F40: 903681 | G40: 1110090 | H40: CERVEJA EISENBAHN IPA LATA 350 ML | I40: 12 | J40: 280 | K40: =J40*24 -> 6720 | L40: =J40*2 -> 560 | M40: =L40/J40 -> 2 | N40: =L40/K40 -> 0.083333333 | O40: 53.94 | P40: =O40/I40 -> 4.495 | Q40: =R40*I40 -> 3.24 | R40: 0.27 | S40: =T40*I40 -> 0 | T40: 0 | U40: =SUM(R40,T40) -> 0.27 | V40: 5.69 | W40: 5.09 | Y40: =L40*(Q40+S40) -> 1814.4 | Z40: =L40*O40 -> 30206.4 | AA40: =L40*12*0.35/100 -> 23.52 | AC40: =SUM(AI40,AL40,AO40) -> 0.26691 | AD40: =SUM(R40,T40) -> 0.27 | AE40: =AC40-AD40 -> -0.00309 | AG40: 76.26 | AH40: =AG40*AA40 -> 1793.6352 | AI40: =AH40/L40/I40 -> 0.26691 | AK40: =AJ40*AA40 -> 0 | AL40: =AK40/L40/I40 -> 0 | AM40: 0 | AN40: =AM40*AA40 -> 0 | AO40: =AN40/L40/I40 -> 0 | AP40: =SUM(AH40,AK40,AN40) -> 1793.6352 | AQ40: =SUM(AI40,AL40,AO40) -> 0.26691 | AR40: =Y40 -> 1814.4 | AS40: =AP40-AR40 -> -20.7648 | AT40: =O40/I40 -> 4.495 | AU40: =AT40-R40-T40 -> 4.225 | AV40: =(W40-AU40)/W40 -> 0.16994106 | AX40: =W40*100% -> 5.09 | AY40: =X40*50% -> 0 | AZ40: =AX40+AY40 -> 5.09 | BC40: Itu | BD40: HNK BR INDUSTRIA DE BEBIDAS LTDA. | BE40: 50.221.019/0001-36 | BF40: 387000650117 | BG40: Av Primo Schincariol | BH40: 2222 | BI40: Chácara Flórida | BJ40: 13312250 | BK40: Itu | BL40: SP
A41: 0.0426 | B41: =VLOOKUP(F41,Planilha3!D:F,3,0) -> 5.8949334 | C41: =B41/A41 -> 138.37872 | D41: Craft | E41: Eisenbahn | F41: 903741 | G41: 1080284 | H41: CERVEJA EISENBAHN IPA LN 355ML | I41: 12 | J41: 175 | K41: =J41*24 -> 4200 | L41: =175*2 -> 350 | M41: =L41/J41 -> 2 | N41: =L41/K41 -> 0.083333333 | O41: 64.37 | P41: =O41/I41 -> 5.3641667 | Q41: =R41*I41 -> 0 | R41: 0 | S41: =T41*I41 -> 0 | T41: 0 | U41: =SUM(R41,T41) -> 0 | V41: 6.79 | W41: 6.79 | Y41: =L41*(Q41+S41) -> 0 | Z41: =L41*O41 -> 22529.5 | AA41: =L41*12*0.355/100 -> 14.91 | AC41: =SUM(AI41,AL41,AO41) -> 0 | AD41: =SUM(R41,T41) -> 0 | AE41: =AC41-AD41 -> 0 | AG41: 0 | AH41: =AG41*AA41 -> 0 | AI41: =AH41/L41/I41 -> 0 | AK41: =AJ41*AA41 -> 0 | AL41: =AK41/L41/I41 -> 0 | AM41: 0 | AN41: =AM41*AA41 -> 0 | AO41: =AN41/L41/I41 -> 0 | AP41: =SUM(AH41,AK41,AN41) -> 0 | AQ41: =SUM(AI41,AL41,AO41) -> 0 | AR41: =Y41 -> 0 | AS41: =AP41-AR41 -> 0 | AT41: =O41/I41 -> 5.3641667 | AU41: =AT41-R41-T41 -> 5.3641667 | AV41: =(W41-AU41)/W41 -> 0.20999018 | AX41: =W41*100% -> 6.79 | AY41: =X41*50% -> 0 | AZ41: =AX41+AY41 -> 6.79 | BC41: Itu | BD41: HNK BR INDUSTRIA DE BEBIDAS LTDA. | BE41: 50.221.019/0001-36 | BF41: 387000650117 | BG41: Av Primo Schincariol | BH41: 2222 | BI41: Chácara Flórida | BJ41: 13312250 | BK41: Itu | BL41: SP
...

Sheet Contra Assaí Ultimo Tri
T1: 0.2 | U1: 0.75
T2: 0.08 | U2: 0.3 | AI2: =SUBTOTAL(9,AI5:AI47) -> 3116511.7 | AL2: =SUBTOTAL(9,AL5:AL47) -> 780649.74 | AO2: =SUBTOTAL(9,AO5:AO47) -> 5525350.1
B3: =SUBTOTAL(9,B5:B47) -> #N/A | W3: SUGESTÃO DE PREÇO OUT'25 | Z3: =SUBTOTAL(9,Z5:Z47) -> 9417451.2 | AB3: =SUBTOTAL(9,AB5:AB47) -> 89092.45 | AD3: Total de Investimento Gerado | AE3: TT Investimento Liberado | AF3: Diferença | AI3: Verba Calendario TPR | AL3: Back Margem | AO3: Verba Adicional | AQ3: =SUBTOTAL(9,AQ5:AQ47) -> 9422511.5 | AW3: Margem entregue no promo
A4: Coeficiente | B4: HL Act Restrito | C4: Em caixas | D4: Categoria | E4: Marcas | F4: CÓDIGO SAP HNK | G4: CÓDIGO | H4: PRODUTO | I4: CX | J4: PALETE | K4: CARGA | L4: QTDE COMPRA | M4: QTDE PALETE | N4: QTDE CARRO | O4: CUSTO CX NF | P4: Custo Unitário | Q4: VERBA SELL IN CX | R4: * VERBA SELL IN UND | S4: VERBA ADIC CX | T4: * VERBA ADIC UND | U4: Total Investimento Liberado | V4: Investimento solicitado pelo Assaí | W4: PREÇO REGULAR | X4: PREÇO PROMO | Y4: PREÇO LIBERADO TELE | Z4: VERBA TOTAL SELL IN | AA4: TOTAL PEDIDO NF | AB4: HL | AH4: R$/HL | AI4: Verba Gerado | AJ4: Verba unidade | AK4: R$/HL | AL4: Verba Gerado | AM4: Verba unidade | AN4: R$/HL | AO4: Verba Gerado | AP4: Verba unidade | AQ4: Gerado total | AR4: Unidade total | AS4: VERBA TOTAL SELL IN | AT4: Saving | AU4: CUSTO UNI. NF | AV4: NOVO CUSTO | AY4: 50% Volume preço Promo | AZ4: 50% Volume preço Televendas | BA4: Preço Médio | BB4: Margem entregue | BD4: Cidade | BE4: Razão social | BF4: CNPJ | BG4: Inscrição estadual | BH4: Endereço | BI4: Número | BJ4: Bairro | BK4: Cidade | BL4: Estado | BM4: Cep
A5: 0.03228 | B5: =VLOOKUP(F5,Planilha3!D:F,3,0) -> 1663.6933 | C5: =B5/A5 -> 51539.444 | D5: Mainstream | E5: Amstel | F5: 904113 | G5: 1052772 | H5: CERVEJA AMSTEL 269ML | I5: 12 | J5: 336 | K5: =J5*24 -> 8064 | L5: 645120 | M5: =L5/J5 -> 1920 | N5: =L5/K5 -> 80 | O5: 33.16 | P5: =O5/I5 -> 2.7633333 | Q5: =R5*I5 -> 0.6 | R5: 0.05 | S5: =T5*I5 -> 3.6 | T5: 0.3 | U5: =SUM(R5,T5) -> 0.35 | V5: 0.35 | W5: =VLOOKUP(F5,'[1]Proposta HNK para Tenda'!$F:$T,15,0) -> 3.29 | X5: =VLOOKUP(F5,'[1]Proposta HNK para Tenda'!$F:$U,16,0) -> 3.09 | Y5: 2.79 | Z5: =L5*(Q5+S5) -> 2709504 | AA5: =L5*O5 -> 21392179 | AB5: =L5*12*0.269/100 -> 20824.474 | AD5: =SUM(AJ5,AM5,AP5) -> 0.3681265 | AE5: =SUM(R5,T5) -> 0.35 | AF5: =AD5-AE5 -> 0.0181265 | AH5: 19.98 | AI5: =AH5*AB5 -> 416072.98 | AJ5: =AI5/L5/I5 -> 0.0537462 | AK5: 23.87 | AL5: =AK5*AB5 -> 497080.18 | AM5: =AL5/L5/I5 -> 0.0642103 | AN5: 93 | AO5: =AN5*AB5 -> 1936676 | AP5: =AO5/L5/I5 -> 0.25017 | AQ5: =SUM(AI5,AL5,AO5) -> 2849829.2 | AR5: =SUM(AJ5,AM5,AP5) -> 0.3681265 | AS5: =Z5 -> 2709504 | AT5: =AQ5-AS5 -> 140325.21 | AU5: =O5/I5 -> 2.7633333 | AV5: =AU5-R5-T5 -> 2.4133333 | AW5: =(X5-AV5)/X5 -> 0.21898598 | AY5: =X5*50% -> 1.545 | AZ5: =Y5*50% -> 1.395 | BA5: =AY5+AZ5 -> 2.94 | BB5: =(X5-Y5)/X5 -> 0.097087379 | BD5: Itu | BE5: HNK BR INDUSTRIA DE BEBIDAS LTDA. | BF5: 50.221.019/0001-36 | BG5: 387000650117 | BH5: Av Primo Schincariol | BI5: 2222 | BJ5: Chácara Flórida | BK5: 13312250 | BL5: Itu | BM5: SP
A6: 0.042 | B6: =VLOOKUP(F6,Planilha3!D:F,3,0) -> 1031.9338 | C6: =B6/A6 -> 24569.852 | D6: Mainstream | E6: Amstel | F6: 904952 | G6: 1193288 | H6: CERVEJA AMSTEL 350ML SLEEK | I6: 12 | J6: 280 | K6: =J6*24 -> 6720 | L6: 302400 | M6: =L6/J6 -> 1080 | N6: =L6/K6 -> 45 | O6: 39.21 | P6: =O6/I6 -> 3.2675 | Q6: =R6*I6 -> 1.2 | R6: 0.1 | S6: =T6*I6 -> 3.24 | T6: 0.27 | U6: =SUM(R6,T6) -> 0.37 | V6: 0.37 | W6: =VLOOKUP(F6,'[1]Proposta HNK para Tenda'!$F:$T,15,0) -> 3.89 | X6: =VLOOKUP(F6,'[1]Proposta HNK para Tenda'!$F:$U,16,0) -> 3.69 | Y6: 3.29 | Z6: =L6*(Q6+S6) -> 1342656 | AA6: =L6*O6 -> 11857104 | AB6: =L6*12*0.35/100 -> 12700.8 | AD6: =SUM(AJ6,AM6,AP6) -> 0.378 | AE6: =SUM(R6,T6) -> 0.37 | AF6: =AD6-AE6 -> 0.008 | AH6: 21.4 | AI6: =AH6*AB6 -> 271797.12 | AJ6: =AI6/L6/I6 -> 0.0749 | AK6: 21.6 | AL6: =AK6*AB6 -> 274337.28 | AM6: =AL6/L6/I6 -> 0.0756 | AN6: 65 | AO6: =AN6*AB6 -> 825552 | AP6: =AO6/L6/I6 -> 0.2275 | AQ6: =SUM(AI6,AL6,AO6) -> 1371686.4 | AR6: =SUM(AJ6,AM6,AP6) -> 0.378 | AS6: =Z6 -> 1342656 | AT6: =AQ6-AS6 -> 29030.4 | AU6: =O6/I6 -> 3.2675 | AV6: =AU6-R6-T6 -> 2.8975 | AW6: =(X6-AV6)/X6 -> 0.21476965 | AY6: =X6*50% -> 1.845 | AZ6: =Y6*50% -> 1.645 | BA6: =AY6+AZ6 -> 3.49 | BB6: =(X6-Y6)/X6 -> 0.10840108 | BD6: Jacarei | BE6: HNK BR INDUSTRIA DE BEBIDAS LTDA. | BF6: 50.221.019/0104-41 | BG6: 392558326113 | BH6: Av Presidente Humberto de Alencar Castelo Branco | BI6: 2911 | BJ6: Conjunto Habitacional Marinho | BK6: 12321150 | BL6: Jacareí | BM6: SP
